Workbook

Sheet 114成績輸入與落點儀表板
A1: 科目 | B1: 我的成績 | C1: 採計條件篩選 | E1: 🎯 志願落點分析系統使用說明
A2: 國文 | B2: 0 | C2: 必須採計 | E2: 1. 請在【B欄】(黃色儲存格) 輸入您的各科實得分數 (0-60分)。
A3: 英文 | B3: 0 | C3: 不拘 | E3: 2. 【新增功能】請在【C欄】(藍色儲存格) 選擇該科目是否必須被採計。
A4: 數學甲 | B4: 0 | C4: 不拘 | E4: - 「不拘」：該科採計或不採計皆可。
A5: 數學乙 | B5: 0 | C5: 不拘 | E5: - 「必須採計」：過濾出『一定有考這科』的校系。
A6: 數學A | B6: 0 | C6: 不拘 | E6: - 「不可採計」：過濾出『絕對不看這科』的校系。
A7: 數學B | B7: 0 | C7: 不拘 | E7: 3. 設定好後，切換至下方的「志願落點分析」工作表查看結果。
A8: 物理 | B8: 0 | C8: 不拘 | E8: 4. 利用「志願落點分析」中 K 欄的【科目篩選結果】，取消勾選「不符合」，即可篩選出完全符合您期望科目的系組！
A9: 化學 | B9: 0 | C9: 不拘
A10: 生物 | B10: 0 | C10: 不拘
A11: 歷史 | B11: 0 | C11: 不拘
A12: 地理 | B12: 0 | C12: 不拘
A13: 公民與社會 | B13: 0 | C13: 不拘
A14: 社會 | B14: 0 | C14: 不拘
A15: 自然 | B15: 0 | C15: 不拘
A16: 術科 | B16: 0 | C16: 不拘

Sheet 114志願落點分析
A1: 系組代碼 | B1: 校名 | C1: 系組名 | D1: 學群分類 | E1: 採計及加權 | F1: 錄取人數 | G1: 最低錄取分數 | H1: 我的加權總分 | I1: 差距 | J1: 預估結果 | K1: 科目篩選結果 | L1: 國 | M1: 英 | N1: 數甲 | O1: 數乙 | P1: 數A | Q1: 數B | R1: 物 | S1: 化 | T1: 生 | U1: 歷 | V1: 地 | W1: 公 | X1: 社 | Y1: 自 | Z1: 術
A2: 0001 | B2: 國立臺灣大學 | C2: 中國文學系 | D2: 文史哲學群 | E2: 國x1.50 英x1.25 歷x1.25 地x1.00 | F2: 20 | G2: 264 | H2: =L2*'114成績輸入與落點儀表板'!$B$2+M2*'114成績輸入與落點儀表板'!$B$3+N2*'114成績輸入與落點儀表板'!$B$4+O2*'114成績輸入與落點儀表板'!$B$5+P2*'114成績輸入與落點儀表板'!$B$6+Q2*'114成績輸入與落點儀表板'!$B$7+R2*'114成績輸入與落點儀表板'!$B$8+S2*'114成績輸入與落點儀表板'!$B$9+T2*'114成績輸入與落點儀表板'!$B$10+U2*'114成績輸入與落點儀表板'!$B$11+V2*'114成績輸入與落點儀表板'!$B$12+W2*'114成績輸入與落點儀表板'!$B$13+X2*'114成績輸入與落點儀表板'!$B$14+Y2*'114成績輸入與落點儀表板'!$B$15+Z2*'114成績輸入與落點儀表板'!$B$16 -> 0 | I2: =H2-G2 -> -264 | J2: =IF(I2>=0, "PASS", "FAIL") -> FAIL | K2: =IF(AND(IF('114成績輸入與落點儀表板'!$C$2="必須採計",L2>0,IF('114成績輸入與落點儀表板'!$C$2="不可採計",L2=0,TRUE)),IF('114成績輸入與落點儀表板'!$C$3="必須採計",M2>0,IF('114成績輸入與落點儀表板'!$C$3="不可採計",M2=0,TRUE)),IF('114成績輸入與落點儀表板'!$C$4="必須採計",N2>0,IF('114成績輸入與落點儀表板'!$C$4="不可採計",N2=0,TRUE)),IF('114成績輸入與落點儀表板'!$C$5="必須採計",O2>0,IF('114成績輸入與落點儀表板'!$C$5="不可採計",O2=0,TRUE)),IF('114成績輸入與落點儀表板'!$C$6="必須採計",P2>0,IF('114成績輸入與落點儀表板'!$C$6="不可採計",P2=0,TRUE)),IF('114成績輸入與落點儀表板'!$C$7="必須採計",Q2>0,IF('114成績輸入與落點儀表板'!$C$7="不可採計",Q2=0,TRUE)),IF('114成績輸入與落點儀表板'!$C$8="必須採計",R2>0,IF('114成績輸入與落點儀表板'!$C$8="不可採計",R2=0,TRUE)),IF('114成績輸入與落點儀表板'!$C$9="必須採計",S2>0,IF('114成績輸入與落點儀表板'!$C$9="不可採計",S2=0,TRUE)),IF('114成績輸入與落點儀表板'!$C$10="必須採計",T2>0,IF('114成績輸入與落點儀表板'!$C$10="不可採計",T2=0,TRUE)),IF('114成績輸入與落點儀表板'!$C$11="必須採計",U2>0,IF('114成績輸入與落點儀表板'!$C$11="不可採計",U2=0,TRUE)),IF('114成績輸入與落點儀表板'!$C$12="必須採計",V2>0,IF('114成績輸入與落點儀表板'!$C$12="不可採計",V2=0,TRUE)),IF('114成績輸入與落點儀表板'!$C$13="必須採計",W2>0,IF('114成績輸入與落點儀表板'!$C$13="不可採計",W2=0,TRUE)),IF('114成績輸入與落點儀表板'!$C$14="必須採計",X2>0,IF('114成績輸入與落點儀表板'!$C$14="不可採計",X2=0,TRUE)),IF('114成績輸入與落點儀表板'!$C$15="必須採計",Y2>0,IF('114成績輸入與落點儀表板'!$C$15="不可採計",Y2=0,TRUE)),IF('114成績輸入與落點儀表板'!$C$16="必須採計",Z2>0,IF('114成績輸入與落點儀表板'!$C$16="不可採計",Z2=0,TRUE))),"✅ 符合","❌ 不符合") -> ✅ 符合 | L2: 1.5 | M2: 1.25 | N2: 0 | O2: 0 | P2: 0 | Q2: 0 | R2: 0 | S2: 0 | T2: 0 | U2: 1.25 | V2: 1 | W2: 0 | X2: 0 | Y2: 0 | Z2: 0
A3: 0002 | B3: 國立臺灣大學 | C3: 外國語文學系 | D3: 外語學群 | E3: 英x2.00 國x1.25 歷x1.00 地x1.00 數乙x1.00 | F3: 43 | G3: 325.75 | H3: =L3*'114成績輸入與落點儀表板'!$B$2+M3*'114成績輸入與落點儀表板'!$B$3+N3*'114成績輸入與落點儀表板'!$B$4+O3*'114成績輸入與落點儀表板'!$B$5+P3*'114成績輸入與落點儀表板'!$B$6+Q3*'114成績輸入與落點儀表板'!$B$7+R3*'114成績輸入與落點儀表板'!$B$8+S3*'114成績輸入與落點儀表板'!$B$9+T3*'114成績輸入與落點儀表板'!$B$10+U3*'114成績輸入與落點儀表板'!$B$11+V3*'114成績輸入與落點儀表板'!$B$12+W3*'114成績輸入與落點儀表板'!$B$13+X3*'114成績輸入與落點儀表板'!$B$14+Y3*'114成績輸入與落點儀表板'!$B$15+Z3*'114成績輸入與落點儀表板'!$B$16 -> 0 | I3: =H3-G3 -> -325.75 | J3: =IF(I3>=0, "PASS", "FAIL") -> FAIL | K3: =IF(AND(IF('114成績輸入與落點儀表板'!$C$2="必須採計",L3>0,IF('114成績輸入與落點儀表板'!$C$2="不可採計",L3=0,TRUE)),IF('114成績輸入與落點儀表板'!$C$3="必須採計",M3>0,IF('114成績輸入與落點儀表板'!$C$3="不可採計",M3=0,TRUE)),IF('114成績輸入與落點儀表板'!$C$4="必須採計",N3>0,IF('114成績輸入與落點儀表板'!$C$4="不可採計",N3=0,TRUE)),IF('114成績輸入與落點儀表板'!$C$5="必須採計",O3>0,IF('114成績輸入與落點儀表板'!$C$5="不可採計",O3=0,TRUE)),IF('114成績輸入與落點儀表板'!$C$6="必須採計",P3>0,IF('114成績輸入與落點儀表板'!$C$6="不可採計",P3=0,TRUE)),IF('114成績輸入與落點儀表板'!$C$7="必須採計",Q3>0,IF('114成績輸入與落點儀表板'!$C$7="不可採計",Q3=0,TRUE)),IF('114成績輸入與落點儀表板'!$C$8="必須採計",R3>0,IF('114成績輸入與落點儀表板'!$C$8="不可採計",R3=0,TRUE)),IF('114成績輸入與落點儀表板'!$C$9="必須採計",S3>0,IF('114成績輸入與落點儀表板'!$C$9="不可採計",S3=0,TRUE)),IF('114成績輸入與落點儀表板'!$C$10="必須採計",T3>0,IF('114成績輸入與落點儀表板'!$C$10="不可採計",T3=0,TRUE)),IF('114成績輸入與落點儀表板'!$C$11="必須採計",U3>0,IF('114成績輸入與落點儀表板'!$C$11="不可採計",U3=0,TRUE)),IF('114成績輸入與落點儀表板'!$C$12="必須採計",V3>0,IF('114成績輸入與落點儀表板'!$C$12="不可採計",V3=0,TRUE)),IF('114成績輸入與落點儀表板'!$C$13="必須採計",W3>0,IF('114成績輸入與落點儀表板'!$C$13="不可採計",W3=0,TRUE)),IF('114成績輸入與落點儀表板'!$C$14="必須採計",X3>0,IF('114成績輸入與落點儀表板'!$C$14="不可採計",X3=0,TRUE)),IF('114成績輸入與落點儀表板'!$C$15="必須採計",Y3>0,IF('114成績輸入與落點儀表板'!$C$15="不可採計",Y3=0,TRUE)),IF('114成績輸入與落點儀表板'!$C$16="必須採計",Z3>0,IF('114成績輸入與落點儀表板'!$C$16="不可採計",Z3=0,TRUE))),"✅ 符合","❌ 不符合") -> ✅ 符合 | L3: 1.25 | M3: 2 | N3: 0 | O3: 1 | P3: 0 | Q3: 0 | R3: 0 | S3: 0 | T3: 0 | U3: 1 | V3: 1 | W3: 0 | X3: 0 | Y3: 0 | Z3: 0
A4: 0003 | B4: 國立臺灣大學 | C4: 歷史學系 | D4: 文史哲學群 | E4: 歷x1.00 國x1.00 英x1.00 地x1.00 公x1.00 | F4: 24 | G4: 260 | H4: =L4*'114成績輸入與落點儀表板'!$B$2+M4*'114成績輸入與落點儀表板'!$B$3+N4*'114成績輸入與落點儀表板'!$B$4+O4*'114成績輸入與落點儀表板'!$B$5+P4*'114成績輸入與落點儀表板'!$B$6+Q4*'114成績輸入與落點儀表板'!$B$7+R4*'114成績輸入與落點儀表板'!$B$8+S4*'114成績輸入與落點儀表板'!$B$9+T4*'114成績輸入與落點儀表板'!$B$10+U4*'114成績輸入與落點儀表板'!$B$11+V4*'114成績輸入與落點儀表板'!$B$12+W4*'114成績輸入與落點儀表板'!$B$13+X4*'114成績輸入與落點儀表板'!$B$14+Y4*'114成績輸入與落點儀表板'!$B$15+Z4*'114成績輸入與落點儀表板'!$B$16 -> 0 | I4: =H4-G4 -> -260 | J4: =IF(I4>=0, "PASS", "FAIL") -> FAIL | K4: =IF(AND(IF('114成績輸入與落點儀表板'!$C$2="必須採計",L4>0,IF('114成績輸入與落點儀表板'!$C$2="不可採計",L4=0,TRUE)),IF('114成績輸入與落點儀表板'!$C$3="必須採計",M4>0,IF('114成績輸入與落點儀表板'!$C$3="不可採計",M4=0,TRUE)),IF('114成績輸入與落點儀表板'!$C$4="必須採計",N4>0,IF('114成績輸入與落點儀表板'!$C$4="不可採計",N4=0,TRUE)),IF('114成績輸入與落點儀表板'!$C$5="必須採計",O4>0,IF('114成績輸入與落點儀表板'!$C$5="不可採計",O4=0,TRUE)),IF('114成績輸入與落點儀表板'!$C$6="必須採計",P4>0,IF('114成績輸入與落點儀表板'!$C$6="不可採計",P4=0,TRUE)),IF('114成績輸入與落點儀表板'!$C$7="必須採計",Q4>0,IF('114成績輸入與落點儀表板'!$C$7="不可採計",Q4=0,TRUE)),IF('114成績輸入與落點儀表板'!$C$8="必須採計",R4>0,IF('114成績輸入與落點儀表板'!$C$8="不可採計",R4=0,TRUE)),IF('114成績輸入與落點儀表板'!$C$9="必須採計",S4>0,IF('114成績輸入與落點儀表板'!$C$9="不可採計",S4=0,TRUE)),IF('114成績輸入與落點儀表板'!$C$10="必須採計",T4>0,IF('114成績輸入與落點儀表板'!$C$10="不可採計",T4=0,TRUE)),IF('114成績輸入與落點儀表板'!$C$11="必須採計",U4>0,IF('114成績輸入與落點儀表板'!$C$11="不可採計",U4=0,TRUE)),IF('114成績輸入與落點儀表板'!$C$12="必須採計",V4>0,IF('114成績輸入與落點儀表板'!$C$12="不可採計",V4=0,TRUE)),IF('114成績輸入與落點儀表板'!$C$13="必須採計",W4>0,IF('114成績輸入與落點儀表板'!$C$13="不可採計",W4=0,TRUE)),IF('114成績輸入與落點儀表板'!$C$14="必須採計",X4>0,IF('114成績輸入與落點儀表板'!$C$14="不可採計",X4=0,TRUE)),IF('114成績輸入與落點儀表板'!$C$15="必須採計",Y4>0,IF('114成績輸入與落點儀表板'!$C$15="不可採計",Y4=0,TRUE)),IF('114成績輸入與落點儀表板'!$C$16="必須採計",Z4>0,IF('114成績輸入與落點儀表板'!$C$16="不可採計",Z4=0,TRUE))),"✅ 符合","❌ 不符合") -> ✅ 符合 | L4: 1 | M4: 1 | N4: 0 | O4: 0 | P4: 0 | Q4: 0 | R4: 0 | S4: 0 | T4: 0 | U4: 1 | V4: 1 | W4: 1 | X4: 0 | Y4: 0 | Z4: 0
A5: 0004 | B5: 國立臺灣大學 | C5: 哲學系 | D5: 文史哲學群 | E5: 國x1.00 英x1.00 歷x1.00 公x1.00 | F5: 23 | G5: 199 | H5: =L5*'114成績輸入與落點儀表板'!$B$2+M5*'114成績輸入與落點儀表板'!$B$3+N5*'114成績輸入與落點儀表板'!$B$4+O5*'114成績輸入與落點儀表板'!$B$5+P5*'114成績輸入與落點儀表板'!$B$6+Q5*'114成績輸入與落點儀表板'!$B$7+R5*'114成績輸入與落點儀表板'!$B$8+S5*'114成績輸入與落點儀表板'!$B$9+T5*'114成績輸入與落點儀表板'!$B$10+U5*'114成績輸入與落點儀表板'!$B$11+V5*'114成績輸入與落點儀表板'!$B$12+W5*'114成績輸入與落點儀表板'!$B$13+X5*'114成績輸入與落點儀表板'!$B$14+Y5*'114成績輸入與落點儀表板'!$B$15+Z5*'114成績輸入與落點儀表板'!$B$16 -> 0 | I5: =H5-G5 -> -199 | J5: =IF(I5>=0, "PASS", "FAIL") -> FAIL | K5: =IF(AND(IF('114成績輸入與落點儀表板'!$C$2="必須採計",L5>0,IF('114成績輸入與落點儀表板'!$C$2="不可採計",L5=0,TRUE)),IF('114成績輸入與落點儀表板'!$C$3="必須採計",M5>0,IF('114成績輸入與落點儀表板'!$C$3="不可採計",M5=0,TRUE)),IF('114成績輸入與落點儀表板'!$C$4="必須採計",N5>0,IF('114成績輸入與落點儀表板'!$C$4="不可採計",N5=0,TRUE)),IF('114成績輸入與落點儀表板'!$C$5="必須採計",O5>0,IF('114成績輸入與落點儀表板'!$C$5="不可採計",O5=0,TRUE)),IF('114成績輸入與落點儀表板'!$C$6="必須採計",P5>0,IF('114成績輸入與落點儀表板'!$C$6="不可採計",P5=0,TRUE)),IF('114成績輸入與落點儀表板'!$C$7="必須採計",Q5>0,IF('114成績輸入與落點儀表板'!$C$7="不可採計",Q5=0,TRUE)),IF('114成績輸入與落點儀表板'!$C$8="必須採計",R5>0,IF('114成績輸入與落點儀表板'!$C$8="不可採計",R5=0,TRUE)),IF('114成績輸入與落點儀表板'!$C$9="必須採計",S5>0,IF('114成績輸入與落點儀表板'!$C$9="不可採計",S5=0,TRUE)),IF('114成績輸入與落點儀表板'!$C$10="必須採計",T5>0,IF('114成績輸入與落點儀表板'!$C$10="不可採計",T5=0,TRUE)),IF('114成績輸入與落點儀表板'!$C$11="必須採計",U5>0,IF('114成績輸入與落點儀表板'!$C$11="不可採計",U5=0,TRUE)),IF('114成績輸入與落點儀表板'!$C$12="必須採計",V5>0,IF('114成績輸入與落點儀表板'!$C$12="不可採計",V5=0,TRUE)),IF('114成績輸入與落點儀表板'!$C$13="必須採計",W5>0,IF('114成績輸入與落點儀表板'!$C$13="不可採計",W5=0,TRUE)),IF('114成績輸入與落點儀表板'!$C$14="必須採計",X5>0,IF('114成績輸入與落點儀表板'!$C$14="不可採計",X5=0,TRUE)),IF('114成績輸入與落點儀表板'!$C$15="必須採計",Y5>0,IF('114成績輸入與落點儀表板'!$C$15="不可採計",Y5=0,TRUE)),IF('114成績輸入與落點儀表板'!$C$16="必須採計",Z5>0,IF('114成績輸入與落點儀表板'!$C$16="不可採計",Z5=0,TRUE))),"✅ 符合","❌ 不符合") -> ✅ 符合 | L5: 1 | M5: 1 | N5: 0 | O5: 0 | P5: 0 | Q5: 0 | R5: 0 | S5: 0 | T5: 0 | U5: 1 | V5: 0 | W5: 1 | X5: 0 | Y5: 0 | Z5: 0
A6: 0005 | B6: 國立臺灣大學 | C6: 人類學系 | D6: 文史哲學群 | E6: 英x1.50 歷x1.00 國x1.00 地x1.00 公x1.00 | F6: 22 | G6: 285.5 | H6: =L6*'114成績輸入與落點儀表板'!$B$2+M6*'114成績輸入與落點儀表板'!$B$3+N6*'114成績輸入與落點儀表板'!$B$4+O6*'114成績輸入與落點儀表板'!$B$5+P6*'114成績輸入與落點儀表板'!$B$6+Q6*'114成績輸入與落點儀表板'!$B$7+R6*'114成績輸入與落點儀表板'!$B$8+S6*'114成績輸入與落點儀表板'!$B$9+T6*'114成績輸入與落點儀表板'!$B$10+U6*'114成績輸入與落點儀表板'!$B$11+V6*'114成績輸入與落點儀表板'!$B$12+W6*'114成績輸入與落點儀表板'!$B$13+X6*'114成績輸入與落點儀表板'!$B$14+Y6*'114成績輸入與落點儀表板'!$B$15+Z6*'114成績輸入與落點儀表板'!$B$16 -> 0 | I6: =H6-G6 -> -285.5 | J6: =IF(I6>=0, "PASS", "FAIL") -> FAIL | K6: =IF(AND(IF('114成績輸入與落點儀表板'!$C$2="必須採計",L6>0,IF('114成績輸入與落點儀表板'!$C$2="不可採計",L6=0,TRUE)),IF('114成績輸入與落點儀表板'!$C$3="必須採計",M6>0,IF('114成績輸入與落點儀表板'!$C$3="不可採計",M6=0,TRUE)),IF('114成績輸入與落點儀表板'!$C$4="必須採計",N6>0,IF('114成績輸入與落點儀表板'!$C$4="不可採計",N6=0,TRUE)),IF('114成績輸入與落點儀表板'!$C$5="必須採計",O6>0,IF('114成績輸入與落點儀表板'!$C$5="不可採計",O6=0,TRUE)),IF('114成績輸入與落點儀表板'!$C$6="必須採計",P6>0,IF('114成績輸入與落點儀表板'!$C$6="不可採計",P6=0,TRUE)),IF('114成績輸入與落點儀表板'!$C$7="必須採計",Q6>0,IF('114成績輸入與落點儀表板'!$C$7="不可採計",Q6=0,TRUE)),IF('114成績輸入與落點儀表板'!$C$8="必須採計",R6>0,IF('114成績輸入與落點儀表板'!$C$8="不可採計",R6=0,TRUE)),IF('114成績輸入與落點儀表板'!$C$9="必須採計",S6>0,IF('114成績輸入與落點儀表板'!$C$9="不可採計",S6=0,TRUE)),IF('114成績輸入與落點儀表板'!$C$10="必須採計",T6>0,IF('114成績輸入與落點儀表板'!$C$10="不可採計",T6=0,TRUE)),IF('114成績輸入與落點儀表板'!$C$11="必須採計",U6>0,IF('114成績輸入與落點儀表板'!$C$11="不可採計",U6=0,TRUE)),IF('114成績輸入與落點儀表板'!$C$12="必須採計",V6>0,IF('114成績輸入與落點儀表板'!$C$12="不可採計",V6=0,TRUE)),IF('114成績輸入與落點儀表板'!$C$13="必須採計",W6>0,IF('114成績輸入與落點儀表板'!$C$13="不可採計",W6=0,TRUE)),IF('114成績輸入與落點儀表板'!$C$14="必須採計",X6>0,IF('114成績輸入與落點儀表板'!$C$14="不可採計",X6=0,TRUE)),IF('114成績輸入與落點儀表板'!$C$15="必須採計",Y6>0,IF('114成績輸入與落點儀表板'!$C$15="不可採計",Y6=0,TRUE)),IF('114成績輸入與落點儀表板'!$C$16="必須採計",Z6>0,IF('114成績輸入與落點儀表板'!$C$16="不可採計",Z6=0,TRUE))),"✅ 符合","❌ 不符合") -> ✅ 符合 | L6: 1 | M6: 1.5 | N6: 0 | O6: 0 | P6: 0 | Q6: 0 | R6: 0 | S6: 0 | T6: 0 | U6: 1 | V6: 1 | W6: 1 | X6: 0 | Y6: 0 | Z6: 0
A7: 0006 | B7: 國立臺灣大學 | C7: 圖書資訊學系 | D7: 資訊學群 | E7: 國x1.25 英x1.25 數乙x1.00 公x1.00 歷x1.00 | F7: 15 | G7: 283.5 | H7: =L7*'114成績輸入與落點儀表板'!$B$2+M7*'114成績輸入與落點儀表板'!$B$3+N7*'114成績輸入與落點儀表板'!$B$4+O7*'114成績輸入與落點儀表板'!$B$5+P7*'114成績輸入與落點儀表板'!$B$6+Q7*'114成績輸入與落點儀表板'!$B$7+R7*'114成績輸入與落點儀表板'!$B$8+S7*'114成績輸入與落點儀表板'!$B$9+T7*'114成績輸入與落點儀表板'!$B$10+U7*'114成績輸入與落點儀表板'!$B$11+V7*'114成績輸入與落點儀表板'!$B$12+W7*'114成績輸入與落點儀表板'!$B$13+X7*'114成績輸入與落點儀表板'!$B$14+Y7*'114成績輸入與落點儀表板'!$B$15+Z7*'114成績輸入與落點儀表板'!$B$16 -> 0 | I7: =H7-G7 -> -283.5 | J7: =IF(I7>=0, "PASS", "FAIL") -> FAIL | K7: =IF(AND(IF('114成績輸入與落點儀表板'!$C$2="必須採計",L7>0,IF('114成績輸入與落點儀表板'!$C$2="不可採計",L7=0,TRUE)),IF('114成績輸入與落點儀表板'!$C$3="必須採計",M7>0,IF('114成績輸入與落點儀表板'!$C$3="不可採計",M7=0,TRUE)),IF('114成績輸入與落點儀表板'!$C$4="必須採計",N7>0,IF('114成績輸入與落點儀表板'!$C$4="不可採計",N7=0,TRUE)),IF('114成績輸入與落點儀表板'!$C$5="必須採計",O7>0,IF('114成績輸入與落點儀表板'!$C$5="不可採計",O7=0,TRUE)),IF('114成績輸入與落點儀表板'!$C$6="必須採計",P7>0,IF('114成績輸入與落點儀表板'!$C$6="不可採計",P7=0,TRUE)),IF('114成績輸入與落點儀表板'!$C$7="必須採計",Q7>0,IF('114成績輸入與落點儀表板'!$C$7="不可採計",Q7=0,TRUE)),IF('114成績輸入與落點儀表板'!$C$8="必須採計",R7>0,IF('114成績輸入與落點儀表板'!$C$8="不可採計",R7=0,TRUE)),IF('114成績輸入與落點儀表板'!$C$9="必須採計",S7>0,IF('114成績輸入與落點儀表板'!$C$9="不可採計",S7=0,TRUE)),IF('114成績輸入與落點儀表板'!$C$10="必須採計",T7>0,IF('114成績輸入與落點儀表板'!$C$10="不可採計",T7=0,TRUE)),IF('114成績輸入與落點儀表板'!$C$11="必須採計",U7>0,IF('114成績輸入與落點儀表板'!$C$11="不可採計",U7=0,TRUE)),IF('114成績輸入與落點儀表板'!$C$12="必須採計",V7>0,IF('114成績輸入與落點儀表板'!$C$12="不可採計",V7=0,TRUE)),IF('114成績輸入與落點儀表板'!$C$13="必須採計",W7>0,IF('114成績輸入與落點儀表板'!$C$13="不可採計",W7=0,TRUE)),IF('114成績輸入與落點儀表板'!$C$14="必須採計",X7>0,IF('114成績輸入與落點儀表板'!$C$14="不可採計",X7=0,TRUE)),IF('114成績輸入與落點儀表板'!$C$15="必須採計",Y7>0,IF('114成績輸入與落點儀表板'!$C$15="不可採計",Y7=0,TRUE)),IF('114成績輸入與落點儀表板'!$C$16="必須採計",Z7>0,IF('114成績輸入與落點儀表板'!$C$16="不可採計",Z7=0,TRUE))),"✅ 符合","❌ 不符合") -> ✅ 符合 | L7: 1.25 | M7: 1.25 | N7: 0 | O7: 1 | P7: 0 | Q7: 0 | R7: 0 | S7: 0 | T7: 0 | U7: 1 | V7: 0 | W7: 1 | X7: 0 | Y7: 0 | Z7: 0
A8: 0007 | B8: 國立臺灣大學 | C8: 日本語文學系 | D8: 外語學群 | E8: 英x1.50 國x1.50 歷x1.00 地x1.00 公x1.00 | F8: 21 | G8: 310 | H8: =L8*'114成績輸入與落點儀表板'!$B$2+M8*'114成績輸入與落點儀表板'!$B$3+N8*'114成績輸入與落點儀表板'!$B$4+O8*'114成績輸入與落點儀表板'!$B$5+P8*'114成績輸入與落點儀表板'!$B$6+Q8*'114成績輸入與落點儀表板'!$B$7+R8*'114成績輸入與落點儀表板'!$B$8+S8*'114成績輸入與落點儀表板'!$B$9+T8*'114成績輸入與落點儀表板'!$B$10+U8*'114成績輸入與落點儀表板'!$B$11+V8*'114成績輸入與落點儀表板'!$B$12+W8*'114成績輸入與落點儀表板'!$B$13+X8*'114成績輸入與落點儀表板'!$B$14+Y8*'114成績輸入與落點儀表板'!$B$15+Z8*'114成績輸入與落點儀表板'!$B$16 -> 0 | I8: =H8-G8 -> -310 | J8: =IF(I8>=0, "PASS", "FAIL") -> FAIL | K8: =IF(AND(IF('114成績輸入與落點儀表板'!$C$2="必須採計",L8>0,IF('114成績輸入與落點儀表板'!$C$2="不可採計",L8=0,TRUE)),IF('114成績輸入與落點儀表板'!$C$3="必須採計",M8>0,IF('114成績輸入與落點儀表板'!$C$3="不可採計",M8=0,TRUE)),IF('114成績輸入與落點儀表板'!$C$4="必須採計",N8>0,IF('114成績輸入與落點儀表板'!$C$4="不可採計",N8=0,TRUE)),IF('114成績輸入與落點儀表板'!$C$5="必須採計",O8>0,IF('114成績輸入與落點儀表板'!$C$5="不可採計",O8=0,TRUE)),IF('114成績輸入與落點儀表板'!$C$6="必須採計",P8>0,IF('114成績輸入與落點儀表板'!$C$6="不可採計",P8=0,TRUE)),IF('114成績輸入與落點儀表板'!$C$7="必須採計",Q8>0,IF('114成績輸入與落點儀表板'!$C$7="不可採計",Q8=0,TRUE)),IF('114成績輸入與落點儀表板'!$C$8="必須採計",R8>0,IF('114成績輸入與落點儀表板'!$C$8="不可採計",R8=0,TRUE)),IF('114成績輸入與落點儀表板'!$C$9="必須採計",S8>0,IF('114成績輸入與落點儀表板'!$C$9="不可採計",S8=0,TRUE)),IF('114成績輸入與落點儀表板'!$C$10="必須採計",T8>0,IF('114成績輸入與落點儀表板'!$C$10="不可採計",T8=0,TRUE)),IF('114成績輸入與落點儀表板'!$C$11="必須採計",U8>0,IF('114成績輸入與落點儀表板'!$C$11="不可採計",U8=0,TRUE)),IF('114成績輸入與落點儀表板'!$C$12="必須採計",V8>0,IF('114成績輸入與落點儀表板'!$C$12="不可採計",V8=0,TRUE)),IF('114成績輸入與落點儀表板'!$C$13="必須採計",W8>0,IF('114成績輸入與落點儀表板'!$C$13="不可採計",W8=0,TRUE)),IF('114成績輸入與落點儀表板'!$C$14="必須採計",X8>0,IF('114成績輸入與落點儀表板'!$C$14="不可採計",X8=0,TRUE)),IF('114成績輸入與落點儀表板'!$C$15="必須採計",Y8>0,IF('114成績輸入與落點儀表板'!$C$15="不可採計",Y8=0,TRUE)),IF('114成績輸入與落點儀表板'!$C$16="必須採計",Z8>0,IF('114成績輸入與落點儀表板'!$C$16="不可採計",Z8=0,TRUE))),"✅ 符合","❌ 不符合") -> ✅ 符合 | L8: 1.5 | M8: 1.5 | N8: 0 | O8: 0 | P8: 0 | Q8: 0 | R8: 0 | S8: 0 | T8: 0 | U8: 1 | V8: 1 | W8: 1 | X8: 0 | Y8: 0 | Z8: 0
A9: 0010 | B9: 國立臺灣大學 | C9: 戲劇學系(男) | D9: 藝術與體育學群 | E9: 英x1.50 國x1.50 數Bx1.00 歷x1.00 地x1.00 | F9: 9 | G9: 278 | H9: =L9*'114成績輸入與落點儀表板'!$B$2+M9*'114成績輸入與落點儀表板'!$B$3+N9*'114成績輸入與落點儀表板'!$B$4+O9*'114成績輸入與落點儀表板'!$B$5+P9*'114成績輸入與落點儀表板'!$B$6+Q9*'114成績輸入與落點儀表板'!$B$7+R9*'114成績輸入與落點儀表板'!$B$8+S9*'114成績輸入與落點儀表板'!$B$9+T9*'114成績輸入與落點儀表板'!$B$10+U9*'114成績輸入與落點儀表板'!$B$11+V9*'114成績輸入與落點儀表板'!$B$12+W9*'114成績輸入與落點儀表板'!$B$13+X9*'114成績輸入與落點儀表板'!$B$14+Y9*'114成績輸入與落點儀表板'!$B$15+Z9*'114成績輸入與落點儀表板'!$B$16 -> 0 | I9: =H9-G9 -> -278 | J9: =IF(I9>=0, "PASS", "FAIL") -> FAIL | K9: =IF(AND(IF('114成績輸入與落點儀表板'!$C$2="必須採計",L9>0,IF('114成績輸入與落點儀表板'!$C$2="不可採計",L9=0,TRUE)),IF('114成績輸入與落點儀表板'!$C$3="必須採計",M9>0,IF('114成績輸入與落點儀表板'!$C$3="不可採計",M9=0,TRUE)),IF('114成績輸入與落點儀表板'!$C$4="必須採計",N9>0,IF('114成績輸入與落點儀表板'!$C$4="不可採計",N9=0,TRUE)),IF('114成績輸入與落點儀表板'!$C$5="必須採計",O9>0,IF('114成績輸入與落點儀表板'!$C$5="不可採計",O9=0,TRUE)),IF('114成績輸入與落點儀表板'!$C$6="必須採計",P9>0,IF('114成績輸入與落點儀表板'!$C$6="不可採計",P9=0,TRUE)),IF('114成績輸入與落點儀表板'!$C$7="必須採計",Q9>0,IF('114成績輸入與落點儀表板'!$C$7="不可採計",Q9=0,TRUE)),IF('114成績輸入與落點儀表板'!$C$8="必須採計",R9>0,IF('114成績輸入與落點儀表板'!$C$8="不可採計",R9=0,TRUE)),IF('114成績輸入與落點儀表板'!$C$9="必須採計",S9>0,IF('114成績輸入與落點儀表板'!$C$9="不可採計",S9=0,TRUE)),IF('114成績輸入與落點儀表板'!$C$10="必須採計",T9>0,IF('114成績輸入與落點儀表板'!$C$10="不可採計",T9=0,TRUE)),IF('114成績輸入與落點儀表板'!$C$11="必須採計",U9>0,IF('114成績輸入與落點儀表板'!$C$11="不可採計",U9=0,TRUE)),IF('114成績輸入與落點儀表板'!$C$12="必須採計",V9>0,IF('114成績輸入與落點儀表板'!$C$12="不可採計",V9=0,TRUE)),IF('114成績輸入與落點儀表板'!$C$13="必須採計",W9>0,IF('114成績輸入與落點儀表板'!$C$13="不可採計",W9=0,TRUE)),IF('114成績輸入與落點儀表板'!$C$14="必須採計",X9>0,IF('114成績輸入與落點儀表板'!$C$14="不可採計",X9=0,TRUE)),IF('114成績輸入與落點儀表板'!$C$15="必須採計",Y9>0,IF('114成績輸入與落點儀表板'!$C$15="不可採計",Y9=0,TRUE)),IF('114成績輸入與落點儀表板'!$C$16="必須採計",Z9>0,IF('114成績輸入與落點儀表板'!$C$16="不可採計",Z9=0,TRUE))),"✅ 符合","❌ 不符合") -> ✅ 符合 | L9: 1.5 | M9: 1.5 | N9: 0 | O9: 0 | P9: 0 | Q9: 1 | R9: 0 | S9: 0 | T9: 0 | U9: 1 | V9: 1 | W9: 0 | X9: 0 | Y9: 0 | Z9: 0
A10: 0011 | B10: 國立臺灣大學 | C10: 戲劇學系(女) | D10: 藝術與體育學群 | E10: 英x1.50 國x1.50 數Bx1.00 歷x1.00 地x1.00 | F10: 10 | G10: 291.5 | H10: =L10*'114成績輸入與落點儀表板'!$B$2+M10*'114成績輸入與落點儀表板'!$B$3+N10*'114成績輸入與落點儀表板'!$B$4+O10*'114成績輸入與落點儀表板'!$B$5+P10*'114成績輸入與落點儀表板'!$B$6+Q10*'114成績輸入與落點儀表板'!$B$7+R10*'114成績輸入與落點儀表板'!$B$8+S10*'114成績輸入與落點儀表板'!$B$9+T10*'114成績輸入與落點儀表板'!$B$10+U10*'114成績輸入與落點儀表板'!$B$11+V10*'114成績輸入與落點儀表板'!$B$12+W10*'114成績輸入與落點儀表板'!$B$13+X10*'114成績輸入與落點儀表板'!$B$14+Y10*'114成績輸入與落點儀表板'!$B$15+Z10*'114成績輸入與落點儀表板'!$B$16 -> 0 | I10: =H10-G10 -> -291.5 | J10: =IF(I10>=0, "PASS", "FAIL") -> FAIL | K10: =IF(AND(IF('114成績輸入與落點儀表板'!$C$2="必須採計",L10>0,IF('114成績輸入與落點儀表板'!$C$2="不可採計",L10=0,TRUE)),IF('114成績輸入與落點儀表板'!$C$3="必須採計",M10>0,IF('114成績輸入與落點儀表板'!$C$3="不可採計",M10=0,TRUE)),IF('114成績輸入與落點儀表板'!$C$4="必須採計",N10>0,IF('114成績輸入與落點儀表板'!$C$4="不可採計",N10=0,TRUE)),IF('114成績輸入與落點儀表板'!$C$5="必須採計",O10>0,IF('114成績輸入與落點儀表板'!$C$5="不可採計",O10=0,TRUE)),IF('114成績輸入與落點儀表板'!$C$6="必須採計",P10>0,IF('114成績輸入與落點儀表板'!$C$6="不可採計",P10=0,TRUE)),IF('114成績輸入與落點儀表板'!$C$7="必須採計",Q10>0,IF('114成績輸入與落點儀表板'!$C$7="不可採計",Q10=0,TRUE)),IF('114成績輸入與落點儀表板'!$C$8="必須採計",R10>0,IF('114成績輸入與落點儀表板'!$C$8="不可採計",R10=0,TRUE)),IF('114成績輸入與落點儀表板'!$C$9="必須採計",S10>0,IF('114成績輸入與落點儀表板'!$C$9="不可採計",S10=0,TRUE)),IF('114成績輸入與落點儀表板'!$C$10="必須採計",T10>0,IF('114成績輸入與落點儀表板'!$C$10="不可採計",T10=0,TRUE)),IF('114成績輸入與落點儀表板'!$C$11="必須採計",U10>0,IF('114成績輸入與落點儀表板'!$C$11="不可採計",U10=0,TRUE)),IF('114成績輸入與落點儀表板'!$C$12="必須採計",V10>0,IF('114成績輸入與落點儀表板'!$C$12="不可採計",V10=0,TRUE)),IF('114成績輸入與落點儀表板'!$C$13="必須採計",W10>0,IF('114成績輸入與落點儀表板'!$C$13="不可採計",W10=0,TRUE)),IF('114成績輸入與落點儀表板'!$C$14="必須採計",X10>0,IF('114成績輸入與落點儀表板'!$C$14="不可採計",X10=0,TRUE)),IF('114成績輸入與落點儀表板'!$C$15="必須採計",Y10>0,IF('114成績輸入與落點儀表板'!$C$15="不可採計",Y10=0,TRUE)),IF('114成績輸入與落點儀表板'!$C$16="必須採計",Z10>0,IF('114成績輸入與落點儀表板'!$C$16="不可採計",Z10=0,TRUE))),"✅ 符合","❌ 不符合") -> ✅ 符合 | L10: 1.5 | M10: 1.5 | N10: 0 | O10: 0 | P10: 0 | Q10: 1 | R10: 0 | S10: 0 | T10: 0 | U10: 1 | V10: 1 | W10: 0 | X10: 0 | Y10: 0 | Z10: 0
A11: 0012 | B11: 國立臺灣大學 | C11: 數學系 | D11: 數理化學群 | E11: 數Ax1.50 數甲x1.50 物x1.00 化x1.00 英x1.00 | F11: 15 | G11: 306.5 | H11: =L11*'114成績輸入與落點儀表板'!$B$2+M11*'114成績輸入與落點儀表板'!$B$3+N11*'114成績輸入與落點儀表板'!$B$4+O11*'114成績輸入與落點儀表板'!$B$5+P11*'114成績輸入與落點儀表板'!$B$6+Q11*'114成績輸入與落點儀表板'!$B$7+R11*'114成績輸入與落點儀表板'!$B$8+S11*'114成績輸入與落點儀表板'!$B$9+T11*'114成績輸入與落點儀表板'!$B$10+U11*'114成績輸入與落點儀表板'!$B$11+V11*'114成績輸入與落點儀表板'!$B$12+W11*'114成績輸入與落點儀表板'!$B$13+X11*'114成績輸入與落點儀表板'!$B$14+Y11*'114成績輸入與落點儀表板'!$B$15+Z11*'114成績輸入與落點儀表板'!$B$16 -> 0 | I11: =H11-G11 -> -306.5 | J11: =IF(I11>=0, "PASS", "FAIL") -> FAIL | K11: =IF(AND(IF('114成績輸入與落點儀表板'!$C$2="必須採計",L11>0,IF('114成績輸入與落點儀表板'!$C$2="不可採計",L11=0,TRUE)),IF('114成績輸入與落點儀表板'!$C$3="必須採計",M11>0,IF('114成績輸入與落點儀表板'!$C$3="不可採計",M11=0,TRUE)),IF('114成績輸入與落點儀表板'!$C$4="必須採計",N11>0,IF('114成績輸入與落點儀表板'!$C$4="不可採計",N11=0,TRUE)),IF('114成績輸入與落點儀表板'!$C$5="必須採計",O11>0,IF('114成績輸入與落點儀表板'!$C$5="不可採計",O11=0,TRUE)),IF('114成績輸入與落點儀表板'!$C$6="必須採計",P11>0,IF('114成績輸入與落點儀表板'!$C$6="不可採計",P11=0,TRUE)),IF('114成績輸入與落點儀表板'!$C$7="必須採計",Q11>0,IF('114成績輸入與落點儀表板'!$C$7="不可採計",Q11=0,TRUE)),IF('114成績輸入與落點儀表板'!$C$8="必須採計",R11>0,IF('114成績輸入與落點儀表板'!$C$8="不可採計",R11=0,TRUE)),IF('114成績輸入與落點儀表板'!$C$9="必須採計",S11>0,IF('114成績輸入與落點儀表板'!$C$9="不可採計",S11=0,TRUE)),IF('114成績輸入與落點儀表板'!$C$10="必須採計",T11>0,IF('114成績輸入與落點儀表板'!$C$10="不可採計",T11=0,TRUE)),IF('114成績輸入與落點儀表板'!$C$11="必須採計",U11>0,IF('114成績輸入與落點儀表板'!$C$11="不可採計",U11=0,TRUE)),IF('114成績輸入與落點儀表板'!$C$12="必須採計",V11>0,IF('114成績輸入與落點儀表板'!$C$12="不可採計",V11=0,TRUE)),IF('114成績輸入與落點儀表板'!$C$13="必須採計",W11>0,IF('114成績輸入與落點儀表板'!$C$13="不可採計",W11=0,TRUE)),IF('114成績輸入與落點儀表板'!$C$14="必須採計",X11>0,IF('114成績輸入與落點儀表板'!$C$14="不可採計",X11=0,TRUE)),IF('114成績輸入與落點儀表板'!$C$15="必須採計",Y11>0,IF('114成績輸入與落點儀表板'!$C$15="不可採計",Y11=0,TRUE)),IF('114成績輸入與落點儀表板'!$C$16="必須採計",Z11>0,IF('114成績輸入與落點儀表板'!$C$16="不可採計",Z11=0,TRUE))),"✅ 符合","❌ 不符合") -> ❌ 不符合 | L11: 0 | M11: 1 | N11: 1.5 | O11: 0 | P11: 1.5 | Q11: 0 | R11: 1 | S11: 1 | T11: 0 | U11: 0 | V11: 0 | W11: 0 | X11: 0 | Y11: 0 | Z11: 0
A12: 0013 | B12: 國立臺灣大學 | C12: 物理學系 | D12: 數理化學群 | E12: 物x1.50 數甲x1.50 英x1.00 化x1.00 | F12: 15 | G12: 280 | H12: =L12*'114成績輸入與落點儀表板'!$B$2+M12*'114成績輸入與落點儀表板'!$B$3+N12*'114成績輸入與落點儀表板'!$B$4+O12*'114成績輸入與落點儀表板'!$B$5+P12*'114成績輸入與落點儀表板'!$B$6+Q12*'114成績輸入與落點儀表板'!$B$7+R12*'114成績輸入與落點儀表板'!$B$8+S12*'114成績輸入與落點儀表板'!$B$9+T12*'114成績輸入與落點儀表板'!$B$10+U12*'114成績輸入與落點儀表板'!$B$11+V12*'114成績輸入與落點儀表板'!$B$12+W12*'114成績輸入與落點儀表板'!$B$13+X12*'114成績輸入與落點儀表板'!$B$14+Y12*'114成績輸入與落點儀表板'!$B$15+Z12*'114成績輸入與落點儀表板'!$B$16 -> 0 | I12: =H12-G12 -> -280 | J12: =IF(I12>=0, "PASS", "FAIL") -> FAIL | K12: =IF(AND(IF('114成績輸入與落點儀表板'!$C$2="必須採計",L12>0,IF('114成績輸入與落點儀表板'!$C$2="不可採計",L12=0,TRUE)),IF('114成績輸入與落點儀表板'!$C$3="必須採計",M12>0,IF('114成績輸入與落點儀表板'!$C$3="不可採計",M12=0,TRUE)),IF('114成績輸入與落點儀表板'!$C$4="必須採計",N12>0,IF('114成績輸入與落點儀表板'!$C$4="不可採計",N12=0,TRUE)),IF('114成績輸入與落點儀表板'!$C$5="必須採計",O12>0,IF('114成績輸入與落點儀表板'!$C$5="不可採計",O12=0,TRUE)),IF('114成績輸入與落點儀表板'!$C$6="必須採計",P12>0,IF('114成績輸入與落點儀表板'!$C$6="不可採計",P12=0,TRUE)),IF('114成績輸入與落點儀表板'!$C$7="必須採計",Q12>0,IF('114成績輸入與落點儀表板'!$C$7="不可採計",Q12=0,TRUE)),IF('114成績輸入與落點儀表板'!$C$8="必須採計",R12>0,IF('114成績輸入與落點儀表板'!$C$8="不可採計",R12=0,TRUE)),IF('114成績輸入與落點儀表板'!$C$9="必須採計",S12>0,IF('114成績輸入與落點儀表板'!$C$9="不可採計",S12=0,TRUE)),IF('114成績輸入與落點儀表板'!$C$10="必須採計",T12>0,IF('114成績輸入與落點儀表板'!$C$10="不可採計",T12=0,TRUE)),IF('114成績輸入與落點儀表板'!$C$11="必須採計",U12>0,IF('114成績輸入與落點儀表板'!$C$11="不可採計",U12=0,TRUE)),IF('114成績輸入與落點儀表板'!$C$12="必須採計",V12>0,IF('114成績輸入與落點儀表板'!$C$12="不可採計",V12=0,TRUE)),IF('114成績輸入與落點儀表板'!$C$13="必須採計",W12>0,IF('114成績輸入與落點儀表板'!$C$13="不可採計",W12=0,TRUE)),IF('114成績輸入與落點儀表板'!$C$14="必須採計",X12>0,IF('114成績輸入與落點儀表板'!$C$14="不可採計",X12=0,TRUE)),IF('114成績輸入與落點儀表板'!$C$15="必須採計",Y12>0,IF('114成績輸入與落點儀表板'!$C$15="不可採計",Y12=0,TRUE)),IF('114成績輸入與落點儀表板'!$C$16="必須採計",Z12>0,IF('114成績輸入與落點儀表板'!$C$16="不可採計",Z12=0,TRUE))),"✅ 符合","❌ 不符合") -> ❌ 不符合 | L12: 0 | M12: 1 | N12: 1.5 | O12: 0 | P12: 0 | Q12: 0 | R12: 1.5 | S12: 1 | T12: 0 | U12: 0 | V12: 0 | W12: 0 | X12: 0 | Y12: 0 | Z12: 0
A13: 0014 | B13: 國立臺灣大學 | C13: 化學系 | D13: 數理化學群 | E13: 化x1.00 英x1.00 數甲x1.00 物x1.00 國x1.00 | F13: 32 | G13: 254 | H13: =L13*'114成績輸入與落點儀表板'!$B$2+M13*'114成績輸入與落點儀表板'!$B$3+N13*'114成績輸入與落點儀表板'!$B$4+O13*'114成績輸入與落點儀表板'!$B$5+P13*'114成績輸入與落點儀表板'!$B$6+Q13*'114成績輸入與落點儀表板'!$B$7+R13*'114成績輸入與落點儀表板'!$B$8+S13*'114成績輸入與落點儀表板'!$B$9+T13*'114成績輸入與落點儀表板'!$B$10+U13*'114成績輸入與落點儀表板'!$B$11+V13*'114成績輸入與落點儀表板'!$B$12+W13*'114成績輸入與落點儀表板'!$B$13+X13*'114成績輸入與落點儀表板'!$B$14+Y13*'114成績輸入與落點儀表板'!$B$15+Z13*'114成績輸入與落點儀表板'!$B$16 -> 0 | I13: =H13-G13 -> -254 | J13: =IF(I13>=0, "PASS", "FAIL") -> FAIL | K13: =IF(AND(IF('114成績輸入與落點儀表板'!$C$2="必須採計",L13>0,IF('114成績輸入與落點儀表板'!$C$2="不可採計",L13=0,TRUE)),IF('114成績輸入與落點儀表板'!$C$3="必須採計",M13>0,IF('114成績輸入與落點儀表板'!$C$3="不可採計",M13=0,TRUE)),IF('114成績輸入與落點儀表板'!$C$4="必須採計",N13>0,IF('114成績輸入與落點儀表板'!$C$4="不可採計",N13=0,TRUE)),IF('114成績輸入與落點儀表板'!$C$5="必須採計",O13>0,IF('114成績輸入與落點儀表板'!$C$5="不可採計",O13=0,TRUE)),IF('114成績輸入與落點儀表板'!$C$6="必須採計",P13>0,IF('114成績輸入與落點儀表板'!$C$6="不可採計",P13=0,TRUE)),IF('114成績輸入與落點儀表板'!$C$7="必須採計",Q13>0,IF('114成績輸入與落點儀表板'!$C$7="不可採計",Q13=0,TRUE)),IF('114成績輸入與落點儀表板'!$C$8="必須採計",R13>0,IF('114成績輸入與落點儀表板'!$C$8="不可採計",R13=0,TRUE)),IF('114成績輸入與落點儀表板'!$C$9="必須採計",S13>0,IF('114成績輸入與落點儀表板'!$C$9="不可採計",S13=0,TRUE)),IF('114成績輸入與落點儀表板'!$C$10="必須採計",T13>0,IF('114成績輸入與落點儀表板'!$C$10="不可採計",T13=0,TRUE)),IF('114成績輸入與落點儀表板'!$C$11="必須採計",U13>0,IF('114成績輸入與落點儀表板'!$C$11="不可採計",U13=0,TRUE)),IF('114成績輸入與落點儀表板'!$C$12="必須採計",V13>0,IF('114成績輸入與落點儀表板'!$C$12="不可採計",V13=0,TRUE)),IF('114成績輸入與落點儀表板'!$C$13="必須採計",W13>0,IF('114成績輸入與落點儀表板'!$C$13="不可採計",W13=0,TRUE)),IF('114成績輸入與落點儀表板'!$C$14="必須採計",X13>0,IF('114成績輸入與落點儀表板'!$C$14="不可採計",X13=0,TRUE)),IF('114成績輸入與落點儀表板'!$C$15="必須採計",Y13>0,IF('114成績輸入與落點儀表板'!$C$15="不可採計",Y13=0,TRUE)),IF('114成績輸入與落點儀表板'!$C$16="必須採計",Z13>0,IF('114成績輸入與落點儀表板'!$C$16="不可採計",Z13=0,TRUE))),"✅ 符合","❌ 不符合") -> ✅ 符合 | L13: 1 | M13: 1 | N13: 1 | O13: 0 | P13: 0 | Q13: 0 | R13: 1 | S13: 1 | T13: 0 | U13: 0 | V13: 0 | W13: 0 | X13: 0 | Y13: 0 | Z13: 0
... A1700: 3373 | B1700: 國立金門大學 | C1700: 護理學系(B組) | D1700: 醫藥衛生學群 | E1700: 國x2.00 公x1.50 英x1.00 | F1700: 6 | G1700: 113 | H1700: =L1700*'114成績輸入與落點儀表板'!$B$2+M1700*'114成績輸入與落點儀表板'!$B$3+N1700*'114成績輸入與落點儀表板'!$B$4+O1700*'114成績輸入與落點儀表板'!$B$5+P1700*'114成績輸入與落點儀表板'!$B$6+Q1700*'114成績輸入與落點儀表板'!$B$7+R1700*'114成績輸入與落點儀表板'!$B$8+S1700*'114成績輸入與落點儀表板'!$B$9+T1700*'114成績輸入與落點儀表板'!$B$10+U1700*'114成績輸入與落點儀表板'!$B$11+V1700*'114成績輸入與落點儀表板'!$B$12+W1700*'114成績輸入與落點儀表板'!$B$13+X1700*'114成績輸入與落點儀表板'!$B$14+Y1700*'114成績輸入與落點儀表板'!$B$15+Z1700*'114成績輸入與落點儀表板'!$B$16 -> 0 | I1700: =H1700-G1700 -> -113 | J1700: =IF(I1700>=0, "PASS", "FAIL") -> FAIL | K1700: =IF(AND(IF('114成績輸入與落點儀表板'!$C$2="必須採計",L1700>0,IF('114成績輸入與落點儀表板'!$C$2="不可採計",L1700=0,TRUE)),IF('114成績輸入與落點儀表板'!$C$3="必須採計",M1700>0,IF('114成績輸入與落點儀表板'!$C$3="不可採計",M1700=0,TRUE)),IF('114成績輸入與落點儀表板'!$C$4="必須採計",N1700>0,IF('114成績輸入與落點儀表板'!$C$4="不可採計",N1700=0,TRUE)),IF('114成績輸入與落點儀表板'!$C$5="必須採計",O1700>0,IF('114成績輸入與落點儀表板'!$C$5="不可採計",O1700=0,TRUE)),IF('114成績輸入與落點儀表板'!$C$6="必須採計",P1700>0,IF('114成績輸入與落點儀表板'!$C$6="不可採計",P1700=0,TRUE)),IF('114成績輸入與落點儀表板'!$C$7="必須採計",Q1700>0,IF('114成績輸入與落點儀表板'!$C$7="不可採計",Q1700=0,TRUE)),IF('114成績輸入與落點儀表板'!$C$8="必須採計",R1700>0,IF('114成績輸入與落點儀表板'!$C$8="不可採計",R1700=0,TRUE)),IF('114成績輸入與落點儀表板'!$C$9="必須採計",S1700>0,IF('114成績輸入與落點儀表板'!$C$9="不可採計",S1700=0,TRUE)),IF('114成績輸入與落點儀表板'!$C$10="必須採計",T1700>0,IF('114成績輸入與落點儀表板'!$C$10="不可採計",T1700=0,TRUE)),IF('114成績輸入與落點儀表板'!$C$11="必須採計",U1700>0,IF('114成績輸入與落點儀表板'!$C$11="不可採計",U1700=0,TRUE)),IF('114成績輸入與落點儀表板'!$C$12="必須採計",V1700>0,IF('114成績輸入與落點儀表板'!$C$12="不可採計",V1700=0,TRUE)),IF('114成績輸入與落點儀表板'!$C$13="必須採計",W1700>0,IF('114成績輸入與落點儀表板'!$C$13="不可採計",W1700=0,TRUE)),IF('114成績輸入與落點儀表板'!$C$14="必須採計",X1700>0,IF('114成績輸入與落點儀表板'!$C$14="不可採計",X1700=0,TRUE)),IF('114成績輸入與落點儀表板'!$C$15="必須採計",Y1700>0,IF('114成績輸入與落點儀表板'!$C$15="不可採計",Y1700=0,TRUE)),IF('114成績輸入與落點儀表板'!$C$16="必須採計",Z1700>0,IF('114成績輸入與落點儀表板'!$C$16="不可採計",Z1700=0,TRUE))),"✅ 符合","❌ 不符合") -> ✅ 符合 | L1700: 2 | M1700: 1 | N1700: 0 | O1700: 0 | P1700: 0 | Q1700: 0 | R1700: 0 | S1700: 0 | T1700: 0 | U1700: 0 | V1700: 0 | W1700: 1.5 | X1700: 0 | Y1700: 0 | Z1700: 0

Sheet 113志願落點分析
A1: 系組代碼 | B1: 校名 | C1: 系組名 | D1: 學群分類 | E1: 採計及加權 | F1: 錄取人數 | G1: 最低錄取分數 | H1: 我的加權總分 | I1: 差距 | J1: 預估結果 | K1: 科目篩選結果 | L1: 國 | M1: 英 | N1: 數甲 | O1: 數乙 | P1: 數A | Q1: 數B | R1: 物 | S1: 化 | T1: 生 | U1: 歷 | V1: 地 | W1: 公 | X1: 社 | Y1: 自 | Z1: 術
A2: 0001 | B2: 國立臺灣大學 | C2: 中國文學系 | D2: 文史哲學群 | E2: 國x1.50 英x1.25 歷x1.25 地x1.00 | F2: 21 | G2: 259 | H2: =L2*'114成績輸入與落點儀表板'!$B$2+M2*'114成績輸入與落點儀表板'!$B$3+N2*'114成績輸入與落點儀表板'!$B$4+O2*'114成績輸入與落點儀表板'!$B$5+P2*'114成績輸入與落點儀表板'!$B$6+Q2*'114成績輸入與落點儀表板'!$B$7+R2*'114成績輸入與落點儀表板'!$B$8+S2*'114成績輸入與落點儀表板'!$B$9+T2*'114成績輸入與落點儀表板'!$B$10+U2*'114成績輸入與落點儀表板'!$B$11+V2*'114成績輸入與落點儀表板'!$B$12+W2*'114成績輸入與落點儀表板'!$B$13+X2*'114成績輸入與落點儀表板'!$B$14+Y2*'114成績輸入與落點儀表板'!$B$15+Z2*'114成績輸入與落點儀表板'!$B$16 -> 0 | I2: =IF(G2="","",H2-G2) -> -259 | J2: =IF(G2="","無錄取資料",IF(I2>=0,"PASS","FAIL")) -> FAIL | K2: =IF(AND(IF('114成績輸入與落點儀表板'!$C$2="必須採計",L2>0,IF('114成績輸入與落點儀表板'!$C$2="不可採計",L2=0,TRUE)),IF('114成績輸入與落點儀表板'!$C$3="必須採計",M2>0,IF('114成績輸入與落點儀表板'!$C$3="不可採計",M2=0,TRUE)),IF('114成績輸入與落點儀表板'!$C$4="必須採計",N2>0,IF('114成績輸入與落點儀表板'!$C$4="不可採計",N2=0,TRUE)),IF('114成績輸入與落點儀表板'!$C$5="必須採計",O2>0,IF('114成績輸入與落點儀表板'!$C$5="不可採計",O2=0,TRUE)),IF('114成績輸入與落點儀表板'!$C$6="必須採計",P2>0,IF('114成績輸入與落點儀表板'!$C$6="不可採計",P2=0,TRUE)),IF('114成績輸入與落點儀表板'!$C$7="必須採計",Q2>0,IF('114成績輸入與落點儀表板'!$C$7="不可採計",Q2=0,TRUE)),IF('114成績輸入與落點儀表板'!$C$8="必須採計",R2>0,IF('114成績輸入與落點儀表板'!$C$8="不可採計",R2=0,TRUE)),IF('114成績輸入與落點儀表板'!$C$9="必須採計",S2>0,IF('114成績輸入與落點儀表板'!$C$9="不可採計",S2=0,TRUE)),IF('114成績輸入與落點儀表板'!$C$10="必須採計",T2>0,IF('114成績輸入與落點儀表板'!$C$10="不可採計",T2=0,TRUE)),IF('114成績輸入與落點儀表板'!$C$11="必須採計",U2>0,IF('114成績輸入與落點儀表板'!$C$11="不可採計",U2=0,TRUE)),IF('114成績輸入與落點儀表板'!$C$12="必須採計",V2>0,IF('114成績輸入與落點儀表板'!$C$12="不可採計",V2=0,TRUE)),IF('114成績輸入與落點儀表板'!$C$13="必須採計",W2>0,IF('114成績輸入與落點儀表板'!$C$13="不可採計",W2=0,TRUE)),IF('114成績輸入與落點儀表板'!$C$14="必須採計",X2>0,IF('114成績輸入與落點儀表板'!$C$14="不可採計",X2=0,TRUE)),IF('114成績輸入與落點儀表板'!$C$15="必須採計",Y2>0,IF('114成績輸入與落點儀表板'!$C$15="不可採計",Y2=0,TRUE)),IF('114成績輸入與落點儀表板'!$C$16="必須採計",Z2>0,IF('114成績輸入與落點儀表板'!$C$16="不可採計",Z2=0,TRUE))),"✅ 符合","❌ 不符合") -> ✅ 符合 | L2: 1.5 | M2: 1.25 | N2: 0 | O2: 0 | P2: 0 | Q2: 0 | R2: 0 | S2: 0 | T2: 0 | U2: 1.25 | V2: 1 | W2: 0 | X2: 0 | Y2: 0 | Z2: 0
A3: 0002 | B3: 國立臺灣大學 | C3: 外國語文學系 | D3: 外語學群 | E3: 英x2.00 國x1.25 歷x1.00 地x1.00 | F3: 42 | G3: 282.75 | H3: =L3*'114成績輸入與落點儀表板'!$B$2+M3*'114成績輸入與落點儀表板'!$B$3+N3*'114成績輸入與落點儀表板'!$B$4+O3*'114成績輸入與落點儀表板'!$B$5+P3*'114成績輸入與落點儀表板'!$B$6+Q3*'114成績輸入與落點儀表板'!$B$7+R3*'114成績輸入與落點儀表板'!$B$8+S3*'114成績輸入與落點儀表板'!$B$9+T3*'114成績輸入與落點儀表板'!$B$10+U3*'114成績輸入與落點儀表板'!$B$11+V3*'114成績輸入與落點儀表板'!$B$12+W3*'114成績輸入與落點儀表板'!$B$13+X3*'114成績輸入與落點儀表板'!$B$14+Y3*'114成績輸入與落點儀表板'!$B$15+Z3*'114成績輸入與落點儀表板'!$B$16 -> 0 | I3: =IF(G3="","",H3-G3) -> -282.75 | J3: =IF(G3="","無錄取資料",IF(I3>=0,"PASS","FAIL")) -> FAIL | K3: =IF(AND(IF('114成績輸入與落點儀表板'!$C$2="必須採計",L3>0,IF('114成績輸入與落點儀表板'!$C$2="不可採計",L3=0,TRUE)),IF('114成績輸入與落點儀表板'!$C$3="必須採計",M3>0,IF('114成績輸入與落點儀表板'!$C$3="不可採計",M3=0,TRUE)),IF('114成績輸入與落點儀表板'!$C$4="必須採計",N3>0,IF('114成績輸入與落點儀表板'!$C$4="不可採計",N3=0,TRUE)),IF('114成績輸入與落點儀表板'!$C$5="必須採計",O3>0,IF('114成績輸入與落點儀表板'!$C$5="不可採計",O3=0,TRUE)),IF('114成績輸入與落點儀表板'!$C$6="必須採計",P3>0,IF('114成績輸入與落點儀表板'!$C$6="不可採計",P3=0,TRUE)),IF('114成績輸入與落點儀表板'!$C$7="必須採計",Q3>0,IF('114成績輸入與落點儀表板'!$C$7="不可採計",Q3=0,TRUE)),IF('114成績輸入與落點儀表板'!$C$8="必須採計",R3>0,IF('114成績輸入與落點儀表板'!$C$8="不可採計",R3=0,TRUE)),IF('114成績輸入與落點儀表板'!$C$9="必須採計",S3>0,IF('114成績輸入與落點儀表板'!$C$9="不可採計",S3=0,TRUE)),IF('114成績輸入與落點儀表板'!$C$10="必須採計",T3>0,IF('114成績輸入與落點儀表板'!$C$10="不可採計",T3=0,TRUE)),IF('114成績輸入與落點儀表板'!$C$11="必須採計",U3>0,IF('114成績輸入與落點儀表板'!$C$11="不可採計",U3=0,TRUE)),IF('114成績輸入與落點儀表板'!$C$12="必須採計",V3>0,IF('114成績輸入與落點儀表板'!$C$12="不可採計",V3=0,TRUE)),IF('114成績輸入與落點儀表板'!$C$13="必須採計",W3>0,IF('114成績輸入與落點儀表板'!$C$13="不可採計",W3=0,TRUE)),IF('114成績輸入與落點儀表板'!$C$14="必須採計",X3>0,IF('114成績輸入與落點儀表板'!$C$14="不可採計",X3=0,TRUE)),IF('114成績輸入與落點儀表板'!$C$15="必須採計",Y3>0,IF('114成績輸入與落點儀表板'!$C$15="不可採計",Y3=0,TRUE)),IF('114成績輸入與落點儀表板'!$C$16="必須採計",Z3>0,IF('114成績輸入與落點儀表板'!$C$16="不可採計",Z3=0,TRUE))),"✅ 符合","❌ 不符合") -> ✅ 符合 | L3: 1.25 | M3: 2 | N3: 0 | O3: 0 | P3: 0 | Q3: 0 | R3: 0 | S3: 0 | T3: 0 | U3: 1 | V3: 1 | W3: 0 | X3: 0 | Y3: 0 | Z3: 0
A4: 0003 | B4: 國立臺灣大學 | C4: 歷史學系 | D4: 文史哲學群 | E4: 歷x1.00 國x1.00 英x1.00 地x1.00 公x1.00 | F4: 22 | G4: 263 | H4: =L4*'114成績輸入與落點儀表板'!$B$2+M4*'114成績輸入與落點儀表板'!$B$3+N4*'114成績輸入與落點儀表板'!$B$4+O4*'114成績輸入與落點儀表板'!$B$5+P4*'114成績輸入與落點儀表板'!$B$6+Q4*'114成績輸入與落點儀表板'!$B$7+R4*'114成績輸入與落點儀表板'!$B$8+S4*'114成績輸入與落點儀表板'!$B$9+T4*'114成績輸入與落點儀表板'!$B$10+U4*'114成績輸入與落點儀表板'!$B$11+V4*'114成績輸入與落點儀表板'!$B$12+W4*'114成績輸入與落點儀表板'!$B$13+X4*'114成績輸入與落點儀表板'!$B$14+Y4*'114成績輸入與落點儀表板'!$B$15+Z4*'114成績輸入與落點儀表板'!$B$16 -> 0 | I4: =IF(G4="","",H4-G4) -> -263 | J4: =IF(G4="","無錄取資料",IF(I4>=0,"PASS","FAIL")) -> FAIL | K4: =IF(AND(IF('114成績輸入與落點儀表板'!$C$2="必須採計",L4>0,IF('114成績輸入與落點儀表板'!$C$2="不可採計",L4=0,TRUE)),IF('114成績輸入與落點儀表板'!$C$3="必須採計",M4>0,IF('114成績輸入與落點儀表板'!$C$3="不可採計",M4=0,TRUE)),IF('114成績輸入與落點儀表板'!$C$4="必須採計",N4>0,IF('114成績輸入與落點儀表板'!$C$4="不可採計",N4=0,TRUE)),IF('114成績輸入與落點儀表板'!$C$5="必須採計",O4>0,IF('114成績輸入與落點儀表板'!$C$5="不可採計",O4=0,TRUE)),IF('114成績輸入與落點儀表板'!$C$6="必須採計",P4>0,IF('114成績輸入與落點儀表板'!$C$6="不可採計",P4=0,TRUE)),IF('114成績輸入與落點儀表板'!$C$7="必須採計",Q4>0,IF('114成績輸入與落點儀表板'!$C$7="不可採計",Q4=0,TRUE)),IF('114成績輸入與落點儀表板'!$C$8="必須採計",R4>0,IF('114成績輸入與落點儀表板'!$C$8="不可採計",R4=0,TRUE)),IF('114成績輸入與落點儀表板'!$C$9="必須採計",S4>0,IF('114成績輸入與落點儀表板'!$C$9="不可採計",S4=0,TRUE)),IF('114成績輸入與落點儀表板'!$C$10="必須採計",T4>0,IF('114成績輸入與落點儀表板'!$C$10="不可採計",T4=0,TRUE)),IF('114成績輸入與落點儀表板'!$C$11="必須採計",U4>0,IF('114成績輸入與落點儀表板'!$C$11="不可採計",U4=0,TRUE)),IF('114成績輸入與落點儀表板'!$C$12="必須採計",V4>0,IF('114成績輸入與落點儀表板'!$C$12="不可採計",V4=0,TRUE)),IF('114成績輸入與落點儀表板'!$C$13="必須採計",W4>0,IF('114成績輸入與落點儀表板'!$C$13="不可採計",W4=0,TRUE)),IF('114成績輸入與落點儀表板'!$C$14="必須採計",X4>0,IF('114成績輸入與落點儀表板'!$C$14="不可採計",X4=0,TRUE)),IF('114成績輸入與落點儀表板'!$C$15="必須採計",Y4>0,IF('114成績輸入與落點儀表板'!$C$15="不可採計",Y4=0,TRUE)),IF('114成績輸入與落點儀表板'!$C$16="必須採計",Z4>0,IF('114成績輸入與落點儀表板'!$C$16="不可採計",Z4=0,TRUE))),"✅ 符合","❌ 不符合") -> ✅ 符合 | L4: 1 | M4: 1 | N4: 0 | O4: 0 | P4: 0 | Q4: 0 | R4: 0 | S4: 0 | T4: 0 | U4: 1 | V4: 1 | W4: 1 | X4: 0 | Y4: 0 | Z4: 0
A5: 0004 | B5: 國立臺灣大學 | C5: 哲學系 | D5: 文史哲學群 | E5: 國x1.00 英x1.00 歷x1.00 公x1.00 | F5: 16 | G5: 203 | H5: =L5*'114成績輸入與落點儀表板'!$B$2+M5*'114成績輸入與落點儀表板'!$B$3+N5*'114成績輸入與落點儀表板'!$B$4+O5*'114成績輸入與落點儀表板'!$B$5+P5*'114成績輸入與落點儀表板'!$B$6+Q5*'114成績輸入與落點儀表板'!$B$7+R5*'114成績輸入與落點儀表板'!$B$8+S5*'114成績輸入與落點儀表板'!$B$9+T5*'114成績輸入與落點儀表板'!$B$10+U5*'114成績輸入與落點儀表板'!$B$11+V5*'114成績輸入與落點儀表板'!$B$12+W5*'114成績輸入與落點儀表板'!$B$13+X5*'114成績輸入與落點儀表板'!$B$14+Y5*'114成績輸入與落點儀表板'!$B$15+Z5*'114成績輸入與落點儀表板'!$B$16 -> 0 | I5: =IF(G5="","",H5-G5) -> -203 | J5: =IF(G5="","無錄取資料",IF(I5>=0,"PASS","FAIL")) -> FAIL | K5: =IF(AND(IF('114成績輸入與落點儀表板'!$C$2="必須採計",L5>0,IF('114成績輸入與落點儀表板'!$C$2="不可採計",L5=0,TRUE)),IF('114成績輸入與落點儀表板'!$C$3="必須採計",M5>0,IF('114成績輸入與落點儀表板'!$C$3="不可採計",M5=0,TRUE)),IF('114成績輸入與落點儀表板'!$C$4="必須採計",N5>0,IF('114成績輸入與落點儀表板'!$C$4="不可採計",N5=0,TRUE)),IF('114成績輸入與落點儀表板'!$C$5="必須採計",O5>0,IF('114成績輸入與落點儀表板'!$C$5="不可採計",O5=0,TRUE)),IF('114成績輸入與落點儀表板'!$C$6="必須採計",P5>0,IF('114成績輸入與落點儀表板'!$C$6="不可採計",P5=0,TRUE)),IF('114成績輸入與落點儀表板'!$C$7="必須採計",Q5>0,IF('114成績輸入與落點儀表板'!$C$7="不可採計",Q5=0,TRUE)),IF('114成績輸入與落點儀表板'!$C$8="必須採計",R5>0,IF('114成績輸入與落點儀表板'!$C$8="不可採計",R5=0,TRUE)),IF('114成績輸入與落點儀表板'!$C$9="必須採計",S5>0,IF('114成績輸入與落點儀表板'!$C$9="不可採計",S5=0,TRUE)),IF('114成績輸入與落點儀表板'!$C$10="必須採計",T5>0,IF('114成績輸入與落點儀表板'!$C$10="不可採計",T5=0,TRUE)),IF('114成績輸入與落點儀表板'!$C$11="必須採計",U5>0,IF('114成績輸入與落點儀表板'!$C$11="不可採計",U5=0,TRUE)),IF('114成績輸入與落點儀表板'!$C$12="必須採計",V5>0,IF('114成績輸入與落點儀表板'!$C$12="不可採計",V5=0,TRUE)),IF('114成績輸入與落點儀表板'!$C$13="必須採計",W5>0,IF('114成績輸入與落點儀表板'!$C$13="不可採計",W5=0,TRUE)),IF('114成績輸入與落點儀表板'!$C$14="必須採計",X5>0,IF('114成績輸入與落點儀表板'!$C$14="不可採計",X5=0,TRUE)),IF('114成績輸入與落點儀表板'!$C$15="必須採計",Y5>0,IF('114成績輸入與落點儀表板'!$C$15="不可採計",Y5=0,TRUE)),IF('114成績輸入與落點儀表板'!$C$16="必須採計",Z5>0,IF('114成績輸入與落點儀表板'!$C$16="不可採計",Z5=0,TRUE))),"✅ 符合","❌ 不符合") -> ✅ 符合 | L5: 1 | M5: 1 | N5: 0 | O5: 0 | P5: 0 | Q5: 0 | R5: 0 | S5: 0 | T5: 0 | U5: 1 | V5: 0 | W5: 1 | X5: 0 | Y5: 0 | Z5: 0
A6: 0005 | B6: 國立臺灣大學 | C6: 人類學系 | D6: 社會與心理學群 | E6: 英x1.50 歷x1.00 國x1.00 地x1.00 公x1.00 | F6: 22 | G6: 282.5 | H6: =L6*'114成績輸入與落點儀表板'!$B$2+M6*'114成績輸入與落點儀表板'!$B$3+N6*'114成績輸入與落點儀表板'!$B$4+O6*'114成績輸入與落點儀表板'!$B$5+P6*'114成績輸入與落點儀表板'!$B$6+Q6*'114成績輸入與落點儀表板'!$B$7+R6*'114成績輸入與落點儀表板'!$B$8+S6*'114成績輸入與落點儀表板'!$B$9+T6*'114成績輸入與落點儀表板'!$B$10+U6*'114成績輸入與落點儀表板'!$B$11+V6*'114成績輸入與落點儀表板'!$B$12+W6*'114成績輸入與落點儀表板'!$B$13+X6*'114成績輸入與落點儀表板'!$B$14+Y6*'114成績輸入與落點儀表板'!$B$15+Z6*'114成績輸入與落點儀表板'!$B$16 -> 0 | I6: =IF(G6="","",H6-G6) -> -282.5 | J6: =IF(G6="","無錄取資料",IF(I6>=0,"PASS","FAIL")) -> FAIL | K6: =IF(AND(IF('114成績輸入與落點儀表板'!$C$2="必須採計",L6>0,IF('114成績輸入與落點儀表板'!$C$2="不可採計",L6=0,TRUE)),IF('114成績輸入與落點儀表板'!$C$3="必須採計",M6>0,IF('114成績輸入與落點儀表板'!$C$3="不可採計",M6=0,TRUE)),IF('114成績輸入與落點儀表板'!$C$4="必須採計",N6>0,IF('114成績輸入與落點儀表板'!$C$4="不可採計",N6=0,TRUE)),IF('114成績輸入與落點儀表板'!$C$5="必須採計",O6>0,IF('114成績輸入與落點儀表板'!$C$5="不可採計",O6=0,TRUE)),IF('114成績輸入與落點儀表板'!$C$6="必須採計",P6>0,IF('114成績輸入與落點儀表板'!$C$6="不可採計",P6=0,TRUE)),IF('114成績輸入與落點儀表板'!$C$7="必須採計",Q6>0,IF('114成績輸入與落點儀表板'!$C$7="不可採計",Q6=0,TRUE)),IF('114成績輸入與落點儀表板'!$C$8="必須採計",R6>0,IF('114成績輸入與落點儀表板'!$C$8="不可採計",R6=0,TRUE)),IF('114成績輸入與落點儀表板'!$C$9="必須採計",S6>0,IF('114成績輸入與落點儀表板'!$C$9="不可採計",S6=0,TRUE)),IF('114成績輸入與落點儀表板'!$C$10="必須採計",T6>0,IF('114成績輸入與落點儀表板'!$C$10="不可採計",T6=0,TRUE)),IF('114成績輸入與落點儀表板'!$C$11="必須採計",U6>0,IF('114成績輸入與落點儀表板'!$C$11="不可採計",U6=0,TRUE)),IF('114成績輸入與落點儀表板'!$C$12="必須採計",V6>0,IF('114成績輸入與落點儀表板'!$C$12="不可採計",V6=0,TRUE)),IF('114成績輸入與落點儀表板'!$C$13="必須採計",W6>0,IF('114成績輸入與落點儀表板'!$C$13="不可採計",W6=0,TRUE)),IF('114成績輸入與落點儀表板'!$C$14="必須採計",X6>0,IF('114成績輸入與落點儀表板'!$C$14="不可採計",X6=0,TRUE)),IF('114成績輸入與落點儀表板'!$C$15="必須採計",Y6>0,IF('114成績輸入與落點儀表板'!$C$15="不可採計",Y6=0,TRUE)),IF('114成績輸入與落點儀表板'!$C$16="必須採計",Z6>0,IF('114成績輸入與落點儀表板'!$C$16="不可採計",Z6=0,TRUE))),"✅ 符合","❌ 不符合") -> ✅ 符合 | L6: 1 | M6: 1.5 | N6: 0 | O6: 0 | P6: 0 | Q6: 0 | R6: 0 | S6: 0 | T6: 0 | U6: 1 | V6: 1 | W6: 1 | X6: 0 | Y6: 0 | Z6: 0
A7: 0006 | B7: 國立臺灣大學 | C7: 圖書資訊學系 | D7: 文史哲學群 | E7: 國x1.25 英x1.25 歷x1.00 公x1.00 | F7: 16 | G7: 238 | H7: =L7*'114成績輸入與落點儀表板'!$B$2+M7*'114成績輸入與落點儀表板'!$B$3+N7*'114成績輸入與落點儀表板'!$B$4+O7*'114成績輸入與落點儀表板'!$B$5+P7*'114成績輸入與落點儀表板'!$B$6+Q7*'114成績輸入與落點儀表板'!$B$7+R7*'114成績輸入與落點儀表板'!$B$8+S7*'114成績輸入與落點儀表板'!$B$9+T7*'114成績輸入與落點儀表板'!$B$10+U7*'114成績輸入與落點儀表板'!$B$11+V7*'114成績輸入與落點儀表板'!$B$12+W7*'114成績輸入與落點儀表板'!$B$13+X7*'114成績輸入與落點儀表板'!$B$14+Y7*'114成績輸入與落點儀表板'!$B$15+Z7*'114成績輸入與落點儀表板'!$B$16 -> 0 | I7: =IF(G7="","",H7-G7) -> -238 | J7: =IF(G7="","無錄取資料",IF(I7>=0,"PASS","FAIL")) -> FAIL | K7: =IF(AND(IF('114成績輸入與落點儀表板'!$C$2="必須採計",L7>0,IF('114成績輸入與落點儀表板'!$C$2="不可採計",L7=0,TRUE)),IF('114成績輸入與落點儀表板'!$C$3="必須採計",M7>0,IF('114成績輸入與落點儀表板'!$C$3="不可採計",M7=0,TRUE)),IF('114成績輸入與落點儀表板'!$C$4="必須採計",N7>0,IF('114成績輸入與落點儀表板'!$C$4="不可採計",N7=0,TRUE)),IF('114成績輸入與落點儀表板'!$C$5="必須採計",O7>0,IF('114成績輸入與落點儀表板'!$C$5="不可採計",O7=0,TRUE)),IF('114成績輸入與落點儀表板'!$C$6="必須採計",P7>0,IF('114成績輸入與落點儀表板'!$C$6="不可採計",P7=0,TRUE)),IF('114成績輸入與落點儀表板'!$C$7="必須採計",Q7>0,IF('114成績輸入與落點儀表板'!$C$7="不可採計",Q7=0,TRUE)),IF('114成績輸入與落點儀表板'!$C$8="必須採計",R7>0,IF('114成績輸入與落點儀表板'!$C$8="不可採計",R7=0,TRUE)),IF('114成績輸入與落點儀表板'!$C$9="必須採計",S7>0,IF('114成績輸入與落點儀表板'!$C$9="不可採計",S7=0,TRUE)),IF('114成績輸入與落點儀表板'!$C$10="必須採計",T7>0,IF('114成績輸入與落點儀表板'!$C$10="不可採計",T7=0,TRUE)),IF('114成績輸入與落點儀表板'!$C$11="必須採計",U7>0,IF('114成績輸入與落點儀表板'!$C$11="不可採計",U7=0,TRUE)),IF('114成績輸入與落點儀表板'!$C$12="必須採計",V7>0,IF('114成績輸入與落點儀表板'!$C$12="不可採計",V7=0,TRUE)),IF('114成績輸入與落點儀表板'!$C$13="必須採計",W7>0,IF('114成績輸入與落點儀表板'!$C$13="不可採計",W7=0,TRUE)),IF('114成績輸入與落點儀表板'!$C$14="必須採計",X7>0,IF('114成績輸入與落點儀表板'!$C$14="不可採計",X7=0,TRUE)),IF('114成績輸入與落點儀表板'!$C$15="必須採計",Y7>0,IF('114成績輸入與落點儀表板'!$C$15="不可採計",Y7=0,TRUE)),IF('114成績輸入與落點儀表板'!$C$16="必須採計",Z7>0,IF('114成績輸入與落點儀表板'!$C$16="不可採計",Z7=0,TRUE))),"✅ 符合","❌ 不符合") -> ✅ 符合 | L7: 1.25 | M7: 1.25 | N7: 0 | O7: 0 | P7: 0 | Q7: 0 | R7: 0 | S7: 0 | T7: 0 | U7: 1 | V7: 0 | W7: 1 | X7: 0 | Y7: 0 | Z7: 0
A8: 0007 | B8: 國立臺灣大學 | C8: 日本語文學系 | D8: 外語學群 | E8: 英x1.50 國x1.50 歷x1.00 地x1.00 公x1.00 | F8: 18 | G8: 317 | H8: =L8*'114成績輸入與落點儀表板'!$B$2+M8*'114成績輸入與落點儀表板'!$B$3+N8*'114成績輸入與落點儀表板'!$B$4+O8*'114成績輸入與落點儀表板'!$B$5+P8*'114成績輸入與落點儀表板'!$B$6+Q8*'114成績輸入與落點儀表板'!$B$7+R8*'114成績輸入與落點儀表板'!$B$8+S8*'114成績輸入與落點儀表板'!$B$9+T8*'114成績輸入與落點儀表板'!$B$10+U8*'114成績輸入與落點儀表板'!$B$11+V8*'114成績輸入與落點儀表板'!$B$12+W8*'114成績輸入與落點儀表板'!$B$13+X8*'114成績輸入與落點儀表板'!$B$14+Y8*'114成績輸入與落點儀表板'!$B$15+Z8*'114成績輸入與落點儀表板'!$B$16 -> 0 | I8: =IF(G8="","",H8-G8) -> -317 | J8: =IF(G8="","無錄取資料",IF(I8>=0,"PASS","FAIL")) -> FAIL | K8: =IF(AND(IF('114成績輸入與落點儀表板'!$C$2="必須採計",L8>0,IF('114成績輸入與落點儀表板'!$C$2="不可採計",L8=0,TRUE)),IF('114成績輸入與落點儀表板'!$C$3="必須採計",M8>0,IF('114成績輸入與落點儀表板'!$C$3="不可採計",M8=0,TRUE)),IF('114成績輸入與落點儀表板'!$C$4="必須採計",N8>0,IF('114成績輸入與落點儀表板'!$C$4="不可採計",N8=0,TRUE)),IF('114成績輸入與落點儀表板'!$C$5="必須採計",O8>0,IF('114成績輸入與落點儀表板'!$C$5="不可採計",O8=0,TRUE)),IF('114成績輸入與落點儀表板'!$C$6="必須採計",P8>0,IF('114成績輸入與落點儀表板'!$C$6="不可採計",P8=0,TRUE)),IF('114成績輸入與落點儀表板'!$C$7="必須採計",Q8>0,IF('114成績輸入與落點儀表板'!$C$7="不可採計",Q8=0,TRUE)),IF('114成績輸入與落點儀表板'!$C$8="必須採計",R8>0,IF('114成績輸入與落點儀表板'!$C$8="不可採計",R8=0,TRUE)),IF('114成績輸入與落點儀表板'!$C$9="必須採計",S8>0,IF('114成績輸入與落點儀表板'!$C$9="不可採計",S8=0,TRUE)),IF('114成績輸入與落點儀表板'!$C$10="必須採計",T8>0,IF('114成績輸入與落點儀表板'!$C$10="不可採計",T8=0,TRUE)),IF('114成績輸入與落點儀表板'!$C$11="必須採計",U8>0,IF('114成績輸入與落點儀表板'!$C$11="不可採計",U8=0,TRUE)),IF('114成績輸入與落點儀表板'!$C$12="必須採計",V8>0,IF('114成績輸入與落點儀表板'!$C$12="不可採計",V8=0,TRUE)),IF('114成績輸入與落點儀表板'!$C$13="必須採計",W8>0,IF('114成績輸入與落點儀表板'!$C$13="不可採計",W8=0,TRUE)),IF('114成績輸入與落點儀表板'!$C$14="必須採計",X8>0,IF('114成績輸入與落點儀表板'!$C$14="不可採計",X8=0,TRUE)),IF('114成績輸入與落點儀表板'!$C$15="必須採計",Y8>0,IF('114成績輸入與落點儀表板'!$C$15="不可採計",Y8=0,TRUE)),IF('114成績輸入與落點儀表板'!$C$16="必須採計",Z8>0,IF('114成績輸入與落點儀表板'!$C$16="不可採計",Z8=0,TRUE))),"✅ 符合","❌ 不符合") -> ✅ 符合 | L8: 1.5 | M8: 1.5 | N8: 0 | O8: 0 | P8: 0 | Q8: 0 | R8: 0 | S8: 0 | T8: 0 | U8: 1 | V8: 1 | W8: 1 | X8: 0 | Y8: 0 | Z8: 0
A9: 0010 | B9: 國立臺灣大學 | C9: 戲劇學系(男) | D9: 藝術與體育學群 | E9: 英x1.50 國x1.50 數Bx1.00 歷x1.00 地x1.00 | F9: 7 | G9: 285.5 | H9: =L9*'114成績輸入與落點儀表板'!$B$2+M9*'114成績輸入與落點儀表板'!$B$3+N9*'114成績輸入與落點儀表板'!$B$4+O9*'114成績輸入與落點儀表板'!$B$5+P9*'114成績輸入與落點儀表板'!$B$6+Q9*'114成績輸入與落點儀表板'!$B$7+R9*'114成績輸入與落點儀表板'!$B$8+S9*'114成績輸入與落點儀表板'!$B$9+T9*'114成績輸入與落點儀表板'!$B$10+U9*'114成績輸入與落點儀表板'!$B$11+V9*'114成績輸入與落點儀表板'!$B$12+W9*'114成績輸入與落點儀表板'!$B$13+X9*'114成績輸入與落點儀表板'!$B$14+Y9*'114成績輸入與落點儀表板'!$B$15+Z9*'114成績輸入與落點儀表板'!$B$16 -> 0 | I9: =IF(G9="","",H9-G9) -> -285.5 | J9: =IF(G9="","無錄取資料",IF(I9>=0,"PASS","FAIL")) -> FAIL | K9: =IF(AND(IF('114成績輸入與落點儀表板'!$C$2="必須採計",L9>0,IF('114成績輸入與落點儀表板'!$C$2="不可採計",L9=0,TRUE)),IF('114成績輸入與落點儀表板'!$C$3="必須採計",M9>0,IF('114成績輸入與落點儀表板'!$C$3="不可採計",M9=0,TRUE)),IF('114成績輸入與落點儀表板'!$C$4="必須採計",N9>0,IF('114成績輸入與落點儀表板'!$C$4="不可採計",N9=0,TRUE)),IF('114成績輸入與落點儀表板'!$C$5="必須採計",O9>0,IF('114成績輸入與落點儀表板'!$C$5="不可採計",O9=0,TRUE)),IF('114成績輸入與落點儀表板'!$C$6="必須採計",P9>0,IF('114成績輸入與落點儀表板'!$C$6="不可採計",P9=0,TRUE)),IF('114成績輸入與落點儀表板'!$C$7="必須採計",Q9>0,IF('114成績輸入與落點儀表板'!$C$7="不可採計",Q9=0,TRUE)),IF('114成績輸入與落點儀表板'!$C$8="必須採計",R9>0,IF('114成績輸入與落點儀表板'!$C$8="不可採計",R9=0,TRUE)),IF('114成績輸入與落點儀表板'!$C$9="必須採計",S9>0,IF('114成績輸入與落點儀表板'!$C$9="不可採計",S9=0,TRUE)),IF('114成績輸入與落點儀表板'!$C$10="必須採計",T9>0,IF('114成績輸入與落點儀表板'!$C$10="不可採計",T9=0,TRUE)),IF('114成績輸入與落點儀表板'!$C$11="必須採計",U9>0,IF('114成績輸入與落點儀表板'!$C$11="不可採計",U9=0,TRUE)),IF('114成績輸入與落點儀表板'!$C$12="必須採計",V9>0,IF('114成績輸入與落點儀表板'!$C$12="不可採計",V9=0,TRUE)),IF('114成績輸入與落點儀表板'!$C$13="必須採計",W9>0,IF('114成績輸入與落點儀表板'!$C$13="不可採計",W9=0,TRUE)),IF('114成績輸入與落點儀表板'!$C$14="必須採計",X9>0,IF('114成績輸入與落點儀表板'!$C$14="不可採計",X9=0,TRUE)),IF('114成績輸入與落點儀表板'!$C$15="必須採計",Y9>0,IF('114成績輸入與落點儀表板'!$C$15="不可採計",Y9=0,TRUE)),IF('114成績輸入與落點儀表板'!$C$16="必須採計",Z9>0,IF('114成績輸入與落點儀表板'!$C$16="不可採計",Z9=0,TRUE))),"✅ 符合","❌ 不符合") -> ✅ 符合 | L9: 1.5 | M9: 1.5 | N9: 0 | O9: 0 | P9: 0 | Q9: 1 | R9: 0 | S9: 0 | T9: 0 | U9: 1 | V9: 1 | W9: 0 | X9: 0 | Y9: 0 | Z9: 0
A10: 0011 | B10: 國立臺灣大學 | C10: 戲劇學系(女) | D10: 藝術與體育學群 | E10: 英x1.50 國x1.50 數Bx1.00 歷x1.00 地x1.00 | F10: 9 | G10: 290.5 | H10: =L10*'114成績輸入與落點儀表板'!$B$2+M10*'114成績輸入與落點儀表板'!$B$3+N10*'114成績輸入與落點儀表板'!$B$4+O10*'114成績輸入與落點儀表板'!$B$5+P10*'114成績輸入與落點儀表板'!$B$6+Q10*'114成績輸入與落點儀表板'!$B$7+R10*'114成績輸入與落點儀表板'!$B$8+S10*'114成績輸入與落點儀表板'!$B$9+T10*'114成績輸入與落點儀表板'!$B$10+U10*'114成績輸入與落點儀表板'!$B$11+V10*'114成績輸入與落點儀表板'!$B$12+W10*'114成績輸入與落點儀表板'!$B$13+X10*'114成績輸入與落點儀表板'!$B$14+Y10*'114成績輸入與落點儀表板'!$B$15+Z10*'114成績輸入與落點儀表板'!$B$16 -> 0 | I10: =IF(G10="","",H10-G10) -> -290.5 | J10: =IF(G10="","無錄取資料",IF(I10>=0,"PASS","FAIL")) -> FAIL | K10: =IF(AND(IF('114成績輸入與落點儀表板'!$C$2="必須採計",L10>0,IF('114成績輸入與落點儀表板'!$C$2="不可採計",L10=0,TRUE)),IF('114成績輸入與落點儀表板'!$C$3="必須採計",M10>0,IF('114成績輸入與落點儀表板'!$C$3="不可採計",M10=0,TRUE)),IF('114成績輸入與落點儀表板'!$C$4="必須採計",N10>0,IF('114成績輸入與落點儀表板'!$C$4="不可採計",N10=0,TRUE)),IF('114成績輸入與落點儀表板'!$C$5="必須採計",O10>0,IF('114成績輸入與落點儀表板'!$C$5="不可採計",O10=0,TRUE)),IF('114成績輸入與落點儀表板'!$C$6="必須採計",P10>0,IF('114成績輸入與落點儀表板'!$C$6="不可採計",P10=0,TRUE)),IF('114成績輸入與落點儀表板'!$C$7="必須採計",Q10>0,IF('114成績輸入與落點儀表板'!$C$7="不可採計",Q10=0,TRUE)),IF('114成績輸入與落點儀表板'!$C$8="必須採計",R10>0,IF('114成績輸入與落點儀表板'!$C$8="不可採計",R10=0,TRUE)),IF('114成績輸入與落點儀表板'!$C$9="必須採計",S10>0,IF('114成績輸入與落點儀表板'!$C$9="不可採計",S10=0,TRUE)),IF('114成績輸入與落點儀表板'!$C$10="必須採計",T10>0,IF('114成績輸入與落點儀表板'!$C$10="不可採計",T10=0,TRUE)),IF('114成績輸入與落點儀表板'!$C$11="必須採計",U10>0,IF('114成績輸入與落點儀表板'!$C$11="不可採計",U10=0,TRUE)),IF('114成績輸入與落點儀表板'!$C$12="必須採計",V10>0,IF('114成績輸入與落點儀表板'!$C$12="不可採計",V10=0,TRUE)),IF('114成績輸入與落點儀表板'!$C$13="必須採計",W10>0,IF('114成績輸入與落點儀表板'!$C$13="不可採計",W10=0,TRUE)),IF('114成績輸入與落點儀表板'!$C$14="必須採計",X10>0,IF('114成績輸入與落點儀表板'!$C$14="不可採計",X10=0,TRUE)),IF('114成績輸入與落點儀表板'!$C$15="必須採計",Y10>0,IF('114成績輸入與落點儀表板'!$C$15="不可採計",Y10=0,TRUE)),IF('114成績輸入與落點儀表板'!$C$16="必須採計",Z10>0,IF('114成績輸入與落點儀表板'!$C$16="不可採計",Z10=0,TRUE))),"✅ 符合","❌ 不符合") -> ✅ 符合 | L10: 1.5 | M10: 1.5 | N10: 0 | O10: 0 | P10: 0 | Q10: 1 | R10: 0 | S10: 0 | T10: 0 | U10: 1 | V10: 1 | W10: 0 | X10: 0 | Y10: 0 | Z10: 0
A11: 0012 | B11: 國立臺灣大學 | C11: 數學系 | D11: 數理化學群 | E11: 數Ax1.50 數甲x1.50 物x1.00 化x1.00 英x1.00 | F11: 17 | G11: 301 | H11: =L11*'114成績輸入與落點儀表板'!$B$2+M11*'114成績輸入與落點儀表板'!$B$3+N11*'114成績輸入與落點儀表板'!$B$4+O11*'114成績輸入與落點儀表板'!$B$5+P11*'114成績輸入與落點儀表板'!$B$6+Q11*'114成績輸入與落點儀表板'!$B$7+R11*'114成績輸入與落點儀表板'!$B$8+S11*'114成績輸入與落點儀表板'!$B$9+T11*'114成績輸入與落點儀表板'!$B$10+U11*'114成績輸入與落點儀表板'!$B$11+V11*'114成績輸入與落點儀表板'!$B$12+W11*'114成績輸入與落點儀表板'!$B$13+X11*'114成績輸入與落點儀表板'!$B$14+Y11*'114成績輸入與落點儀表板'!$B$15+Z11*'114成績輸入與落點儀表板'!$B$16 -> 0 | I11: =IF(G11="","",H11-G11) -> -301 | J11: =IF(G11="","無錄取資料",IF(I11>=0,"PASS","FAIL")) -> FAIL | K11: =IF(AND(IF('114成績輸入與落點儀表板'!$C$2="必須採計",L11>0,IF('114成績輸入與落點儀表板'!$C$2="不可採計",L11=0,TRUE)),IF('114成績輸入與落點儀表板'!$C$3="必須採計",M11>0,IF('114成績輸入與落點儀表板'!$C$3="不可採計",M11=0,TRUE)),IF('114成績輸入與落點儀表板'!$C$4="必須採計",N11>0,IF('114成績輸入與落點儀表板'!$C$4="不可採計",N11=0,TRUE)),IF('114成績輸入與落點儀表板'!$C$5="必須採計",O11>0,IF('114成績輸入與落點儀表板'!$C$5="不可採計",O11=0,TRUE)),IF('114成績輸入與落點儀表板'!$C$6="必須採計",P11>0,IF('114成績輸入與落點儀表板'!$C$6="不可採計",P11=0,TRUE)),IF('114成績輸入與落點儀表板'!$C$7="必須採計",Q11>0,IF('114成績輸入與落點儀表板'!$C$7="不可採計",Q11=0,TRUE)),IF('114成績輸入與落點儀表板'!$C$8="必須採計",R11>0,IF('114成績輸入與落點儀表板'!$C$8="不可採計",R11=0,TRUE)),IF('114成績輸入與落點儀表板'!$C$9="必須採計",S11>0,IF('114成績輸入與落點儀表板'!$C$9="不可採計",S11=0,TRUE)),IF('114成績輸入與落點儀表板'!$C$10="必須採計",T11>0,IF('114成績輸入與落點儀表板'!$C$10="不可採計",T11=0,TRUE)),IF('114成績輸入與落點儀表板'!$C$11="必須採計",U11>0,IF('114成績輸入與落點儀表板'!$C$11="不可採計",U11=0,TRUE)),IF('114成績輸入與落點儀表板'!$C$12="必須採計",V11>0,IF('114成績輸入與落點儀表板'!$C$12="不可採計",V11=0,TRUE)),IF('114成績輸入與落點儀表板'!$C$13="必須採計",W11>0,IF('114成績輸入與落點儀表板'!$C$13="不可採計",W11=0,TRUE)),IF('114成績輸入與落點儀表板'!$C$14="必須採計",X11>0,IF('114成績輸入與落點儀表板'!$C$14="不可採計",X11=0,TRUE)),IF('114成績輸入與落點儀表板'!$C$15="必須採計",Y11>0,IF('114成績輸入與落點儀表板'!$C$15="不可採計",Y11=0,TRUE)),IF('114成績輸入與落點儀表板'!$C$16="必須採計",Z11>0,IF('114成績輸入與落點儀表板'!$C$16="不可採計",Z11=0,TRUE))),"✅ 符合","❌ 不符合") -> ❌ 不符合 | L11: 0 | M11: 1 | N11: 1.5 | O11: 0 | P11: 1.5 | Q11: 0 | R11: 1 | S11: 1 | T11: 0 | U11: 0 | V11: 0 | W11: 0 | X11: 0 | Y11: 0 | Z11: 0
A12: 0013 | B12: 國立臺灣大學 | C12: 物理學系 | D12: 數理化學群 | E12: 物x1.50 數甲x1.50 英x1.00 化x1.00 | F12: 22 | G12: 266.5 | H12: =L12*'114成績輸入與落點儀表板'!$B$2+M12*'114成績輸入與落點儀表板'!$B$3+N12*'114成績輸入與落點儀表板'!$B$4+O12*'114成績輸入與落點儀表板'!$B$5+P12*'114成績輸入與落點儀表板'!$B$6+Q12*'114成績輸入與落點儀表板'!$B$7+R12*'114成績輸入與落點儀表板'!$B$8+S12*'114成績輸入與落點儀表板'!$B$9+T12*'114成績輸入與落點儀表板'!$B$10+U12*'114成績輸入與落點儀表板'!$B$11+V12*'114成績輸入與落點儀表板'!$B$12+W12*'114成績輸入與落點儀表板'!$B$13+X12*'114成績輸入與落點儀表板'!$B$14+Y12*'114成績輸入與落點儀表板'!$B$15+Z12*'114成績輸入與落點儀表板'!$B$16 -> 0 | I12: =IF(G12="","",H12-G12) -> -266.5 | J12: =IF(G12="","無錄取資料",IF(I12>=0,"PASS","FAIL")) -> FAIL | K12: =IF(AND(IF('114成績輸入與落點儀表板'!$C$2="必須採計",L12>0,IF('114成績輸入與落點儀表板'!$C$2="不可採計",L12=0,TRUE)),IF('114成績輸入與落點儀表板'!$C$3="必須採計",M12>0,IF('114成績輸入與落點儀表板'!$C$3="不可採計",M12=0,TRUE)),IF('114成績輸入與落點儀表板'!$C$4="必須採計",N12>0,IF('114成績輸入與落點儀表板'!$C$4="不可採計",N12=0,TRUE)),IF('114成績輸入與落點儀表板'!$C$5="必須採計",O12>0,IF('114成績輸入與落點儀表板'!$C$5="不可採計",O12=0,TRUE)),IF('114成績輸入與落點儀表板'!$C$6="必須採計",P12>0,IF('114成績輸入與落點儀表板'!$C$6="不可採計",P12=0,TRUE)),IF('114成績輸入與落點儀表板'!$C$7="必須採計",Q12>0,IF('114成績輸入與落點儀表板'!$C$7="不可採計",Q12=0,TRUE)),IF('114成績輸入與落點儀表板'!$C$8="必須採計",R12>0,IF('114成績輸入與落點儀表板'!$C$8="不可採計",R12=0,TRUE)),IF('114成績輸入與落點儀表板'!$C$9="必須採計",S12>0,IF('114成績輸入與落點儀表板'!$C$9="不可採計",S12=0,TRUE)),IF('114成績輸入與落點儀表板'!$C$10="必須採計",T12>0,IF('114成績輸入與落點儀表板'!$C$10="不可採計",T12=0,TRUE)),IF('114成績輸入與落點儀表板'!$C$11="必須採計",U12>0,IF('114成績輸入與落點儀表板'!$C$11="不可採計",U12=0,TRUE)),IF('114成績輸入與落點儀表板'!$C$12="必須採計",V12>0,IF('114成績輸入與落點儀表板'!$C$12="不可採計",V12=0,TRUE)),IF('114成績輸入與落點儀表板'!$C$13="必須採計",W12>0,IF('114成績輸入與落點儀表板'!$C$13="不可採計",W12=0,TRUE)),IF('114成績輸入與落點儀表板'!$C$14="必須採計",X12>0,IF('114成績輸入與落點儀表板'!$C$14="不可採計",X12=0,TRUE)),IF('114成績輸入與落點儀表板'!$C$15="必須採計",Y12>0,IF('114成績輸入與落點儀表板'!$C$15="不可採計",Y12=0,TRUE)),IF('114成績輸入與落點儀表板'!$C$16="必須採計",Z12>0,IF('114成績輸入與落點儀表板'!$C$16="不可採計",Z12=0,TRUE))),"✅ 符合","❌ 不符合") -> ❌ 不符合 | L12: 0 | M12: 1 | N12: 1.5 | O12: 0 | P12: 0 | Q12: 0 | R12: 1.5 | S12: 1 | T12: 0 | U12: 0 | V12: 0 | W12: 0 | X12: 0 | Y12: 0 | Z12: 0
A13: 0014 | B13: 國立臺灣大學 | C13: 化學系 | D13: 數理化學群 | E13: 化x1.00 英x1.00 數甲x1.00 物x1.00 國x1.00 | F13: 30 | G13: 250 | H13: =L13*'114成績輸入與落點儀表板'!$B$2+M13*'114成績輸入與落點儀表板'!$B$3+N13*'114成績輸入與落點儀表板'!$B$4+O13*'114成績輸入與落點儀表板'!$B$5+P13*'114成績輸入與落點儀表板'!$B$6+Q13*'114成績輸入與落點儀表板'!$B$7+R13*'114成績輸入與落點儀表板'!$B$8+S13*'114成績輸入與落點儀表板'!$B$9+T13*'114成績輸入與落點儀表板'!$B$10+U13*'114成績輸入與落點儀表板'!$B$11+V13*'114成績輸入與落點儀表板'!$B$12+W13*'114成績輸入與落點儀表板'!$B$13+X13*'114成績輸入與落點儀表板'!$B$14+Y13*'114成績輸入與落點儀表板'!$B$15+Z13*'114成績輸入與落點儀表板'!$B$16 -> 0 | I13: =IF(G13="","",H13-G13) -> -250 | J13: =IF(G13="","無錄取資料",IF(I13>=0,"PASS","FAIL")) -> FAIL | K13: =IF(AND(IF('114成績輸入與落點儀表板'!$C$2="必須採計",L13>0,IF('114成績輸入與落點儀表板'!$C$2="不可採計",L13=0,TRUE)),IF('114成績輸入與落點儀表板'!$C$3="必須採計",M13>0,IF('114成績輸入與落點儀表板'!$C$3="不可採計",M13=0,TRUE)),IF('114成績輸入與落點儀表板'!$C$4="必須採計",N13>0,IF('114成績輸入與落點儀表板'!$C$4="不可採計",N13=0,TRUE)),IF('114成績輸入與落點儀表板'!$C$5="必須採計",O13>0,IF('114成績輸入與落點儀表板'!$C$5="不可採計",O13=0,TRUE)),IF('114成績輸入與落點儀表板'!$C$6="必須採計",P13>0,IF('114成績輸入與落點儀表板'!$C$6="不可採計",P13=0,TRUE)),IF('114成績輸入與落點儀表板'!$C$7="必須採計",Q13>0,IF('114成績輸入與落點儀表板'!$C$7="不可採計",Q13=0,TRUE)),IF('114成績輸入與落點儀表板'!$C$8="必須採計",R13>0,IF('114成績輸入與落點儀表板'!$C$8="不可採計",R13=0,TRUE)),IF('114成績輸入與落點儀表板'!$C$9="必須採計",S13>0,IF('114成績輸入與落點儀表板'!$C$9="不可採計",S13=0,TRUE)),IF('114成績輸入與落點儀表板'!$C$10="必須採計",T13>0,IF('114成績輸入與落點儀表板'!$C$10="不可採計",T13=0,TRUE)),IF('114成績輸入與落點儀表板'!$C$11="必須採計",U13>0,IF('114成績輸入與落點儀表板'!$C$11="不可採計",U13=0,TRUE)),IF('114成績輸入與落點儀表板'!$C$12="必須採計",V13>0,IF('114成績輸入與落點儀表板'!$C$12="不可採計",V13=0,TRUE)),IF('114成績輸入與落點儀表板'!$C$13="必須採計",W13>0,IF('114成績輸入與落點儀表板'!$C$13="不可採計",W13=0,TRUE)),IF('114成績輸入與落點儀表板'!$C$14="必須採計",X13>0,IF('114成績輸入與落點儀表板'!$C$14="不可採計",X13=0,TRUE)),IF('114成績輸入與落點儀表板'!$C$15="必須採計",Y13>0,IF('114成績輸入與落點儀表板'!$C$15="不可採計",Y13=0,TRUE)),IF('114成績輸入與落點儀表板'!$C$16="必須採計",Z13>0,IF('114成績輸入與落點儀表板'!$C$16="不可採計",Z13=0,TRUE))),"✅ 符合","❌ 不符合") -> ✅ 符合 | L13: 1 | M13: 1 | N13: 1 | O13: 0 | P13: 0 | Q13: 0 | R13: 1 | S13: 1 | T13: 0 | U13: 0 | V13: 0 | W13: 0 | X13: 0 | Y13: 0 | Z13: 0
... A671: 1236 | B671: 中國文化大學 | C671: 美術學系 | D671: 藝術與體育學群 | E671: 國x2.00 術x2.00 歷x1.00 地x1.00 英x1.00 | F671: 7 | G671: 198.92 | H671: =L671*'114成績輸入與落點儀表板'!$B$2+M671*'114成績輸入與落點儀表板'!$B$3+N671*'114成績輸入與落點儀表板'!$B$4+O671*'114成績輸入與落點儀表板'!$B$5+P671*'114成績輸入與落點儀表板'!$B$6+Q671*'114成績輸入與落點儀表板'!$B$7+R671*'114成績輸入與落點儀表板'!$B$8+S671*'114成績輸入與落點儀表板'!$B$9+T671*'114成績輸入與落點儀表板'!$B$10+U671*'114成績輸入與落點儀表板'!$B$11+V671*'114成績輸入與落點儀表板'!$B$12+W671*'114成績輸入與落點儀表板'!$B$13+X671*'114成績輸入與落點儀表板'!$B$14+Y671*'114成績輸入與落點儀表板'!$B$15+Z671*'114成績輸入與落點儀表板'!$B$16 -> 0 | I671: =IF(G671="","",H671-G671) -> -198.92 | J671: =IF(G671="","無錄取資料",IF(I671>=0,"PASS","FAIL")) -> FAIL | K671: =IF(AND(IF('114成績輸入與落點儀表板'!$C$2="必須採計",L671>0,IF('114成績輸入與落點儀表板'!$C$2="不可採計",L671=0,TRUE)),IF('114成績輸入與落點儀表板'!$C$3="必須採計",M671>0,IF('114成績輸入與落點儀表板'!$C$3="不可採計",M671=0,TRUE)),IF('114成績輸入與落點儀表板'!$C$4="必須採計",N671>0,IF('114成績輸入與落點儀表板'!$C$4="不可採計",N671=0,TRUE)),IF('114成績輸入與落點儀表板'!$C$5="必須採計",O671>0,IF('114成績輸入與落點儀表板'!$C$5="不可採計",O671=0,TRUE)),IF('114成績輸入與落點儀表板'!$C$6="必須採計",P671>0,IF('114成績輸入與落點儀表板'!$C$6="不可採計",P671=0,TRUE)),IF('114成績輸入與落點儀表板'!$C$7="必須採計",Q671>0,IF('114成績輸入與落點儀表板'!$C$7="不可採計",Q671=0,TRUE)),IF('114成績輸入與落點儀表板'!$C$8="必須採計",R671>0,IF('114成績輸入與落點儀表板'!$C$8="不可採計",R671=0,TRUE)),IF('114成績輸入與落點儀表板'!$C$9="必須採計",S671>0,IF('114成績輸入與落點儀表板'!$C$9="不可採計",S671=0,TRUE)),IF('114成績輸入與落點儀表板'!$C$10="必須採計",T671>0,IF('114成績輸入與落點儀表板'!$C$10="不可採計",T671=0,TRUE)),IF('114成績輸入與落點儀表板'!$C$11="必須採計",U671>0,IF('114成績輸入與落點儀表板'!$C$11="不可採計",U671=0,TRUE)),IF('114成績輸入與落點儀表板'!$C$12="必須採計",V671>0,IF('114成績輸入與落點儀表板'!$C$12="不可採計",V671=0,TRUE)),IF('114成績輸入與落點儀表板'!$C$13="必須採計",W671>0,IF('114成績輸入與落點儀表板'!$C$13="不可採計",W671=0,TRUE)),IF('114成績輸入與落點儀表板'!$C$14="必須採計",X671>0,IF('114成績輸入與落點儀表板'!$C$14="不可採計",X671=0,TRUE)),IF('114成績輸入與落點儀表板'!$C$15="必須採計",Y671>0,IF('114成績輸入與落點儀表板'!$C$15="不可採計",Y671=0,TRUE)),IF('114成績輸入與落點儀表板'!$C$16="必須採計",Z671>0,IF('114成績輸入與落點儀表板'!$C$16="不可採計",Z671=0,TRUE))),"✅ 符合","❌ 不符合") -> ✅ 符合 | L671: 2 | M671: 1 | N671: 0 | O671: 0 | P671: 0 | Q671: 0 | R671: 0 | S671: 0 | T671: 0 | U671: 1 | V671: 1 | W671: 0 | X671: 0 | Y671: 0 | Z671: 2
A672: 1237 | B672: 中國文化大學 | C672: 音樂學系A組 | D672: 藝術與體育學群 | E672: 術x2.00 國x1.00 英x1.00 歷x1.00 | F672: 0 | H672: =L672*'114成績輸入與落點儀表板'!$B$2+M672*'114成績輸入與落點儀表板'!$B$3+N672*'114成績輸入與落點儀表板'!$B$4+O672*'114成績輸入與落點儀表板'!$B$5+P672*'114成績輸入與落點儀表板'!$B$6+Q672*'114成績輸入與落點儀表板'!$B$7+R672*'114成績輸入與落點儀表板'!$B$8+S672*'114成績輸入與落點儀表板'!$B$9+T672*'114成績輸入與落點儀表板'!$B$10+U672*'114成績輸入與落點儀表板'!$B$11+V672*'114成績輸入與落點儀表板'!$B$12+W672*'114成績輸入與落點儀表板'!$B$13+X672*'114成績輸入與落點儀表板'!$B$14+Y672*'114成績輸入與落點儀表板'!$B$15+Z672*'114成績輸入與落點儀表板'!$B$16 -> 0 | I672: =IF(G672="","",H672-G672) | J672: =IF(G672="","無錄取資料",IF(I672>=0,"PASS","FAIL")) -> 無錄取資料 | K672: =IF(AND(IF('114成績輸入與落點儀表板'!$C$2="必須採計",L672>0,IF('114成績輸入與落點儀表板'!$C$2="不可採計",L672=0,TRUE)),IF('114成績輸入與落點儀表板'!$C$3="必須採計",M672>0,IF('114成績輸入與落點儀表板'!$C$3="不可採計",M672=0,TRUE)),IF('114成績輸入與落點儀表板'!$C$4="必須採計",N672>0,IF('114成績輸入與落點儀表板'!$C$4="不可採計",N672=0,TRUE)),IF('114成績輸入與落點儀表板'!$C$5="必須採計",O672>0,IF('114成績輸入與落點儀表板'!$C$5="不可採計",O672=0,TRUE)),IF('114成績輸入與落點儀表板'!$C$6="必須採計",P672>0,IF('114成績輸入與落點儀表板'!$C$6="不可採計",P672=0,TRUE)),IF('114成績輸入與落點儀表板'!$C$7="必須採計",Q672>0,IF('114成績輸入與落點儀表板'!$C$7="不可採計",Q672=0,TRUE)),IF('114成績輸入與落點儀表板'!$C$8="必須採計",R672>0,IF('114成績輸入與落點儀表板'!$C$8="不可採計",R672=0,TRUE)),IF('114成績輸入與落點儀表板'!$C$9="必須採計",S672>0,IF('114成績輸入與落點儀表板'!$C$9="不可採計",S672=0,TRUE)),IF('114成績輸入與落點儀表板'!$C$10="必須採計",T672>0,IF('114成績輸入與落點儀表板'!$C$10="不可採計",T672=0,TRUE)),IF('114成績輸入與落點儀表板'!$C$11="必須採計",U672>0,IF('114成績輸入與落點儀表板'!$C$11="不可採計",U672=0,TRUE)),IF('114成績輸入與落點儀表板'!$C$12="必須採計",V672>0,IF('114成績輸入與落點儀表板'!$C$12="不可採計",V672=0,TRUE)),IF('114成績輸入與落點儀表板'!$C$13="必須採計",W672>0,IF('114成績輸入與落點儀表板'!$C$13="不可採計",W672=0,TRUE)),IF('114成績輸入與落點儀表板'!$C$14="必須採計",X672>0,IF('114成績輸入與落點儀表板'!$C$14="不可採計",X672=0,TRUE)),IF('114成績輸入與落點儀表板'!$C$15="必須採計",Y672>0,IF('114成績輸入與落點儀表板'!$C$15="不可採計",Y672=0,TRUE)),IF('114成績輸入與落點儀表板'!$C$16="必須採計",Z672>0,IF('114成績輸入與落點儀表板'!$C$16="不可採計",Z672=0,TRUE))),"✅ 符合","❌ 不符合") -> ✅ 符合 | L672: 1 | M672: 1 | N672: 0 | O672: 0 | P672: 0 | Q672: 0 | R672: 0 | S672: 0 | T672: 0 | U672: 1 | V672: 0 | W672: 0 | X672: 0 | Y672: 0 | Z672: 2
A673: 1240 | B673: 中國文化大學 | C673: 音樂學系B組 | D673: 藝術與體育學群 | E673: 國x2.00 英x1.50 歷x1.00 | F673: 2 | G673: 88 | H673: =L673*'114成績輸入與落點儀表板'!$B$2+M673*'114成績輸入與落點儀表板'!$B$3+N673*'114成績輸入與落點儀表板'!$B$4+O673*'114成績輸入與落點儀表板'!$B$5+P673*'114成績輸入與落點儀表板'!$B$6+Q673*'114成績輸入與落點儀表板'!$B$7+R673*'114成績輸入與落點儀表板'!$B$8+S673*'114成績輸入與落點儀表板'!$B$9+T673*'114成績輸入與落點儀表板'!$B$10+U673*'114成績輸入與落點儀表板'!$B$11+V673*'114成績輸入與落點儀表板'!$B$12+W673*'114成績輸入與落點儀表板'!$B$13+X673*'114成績輸入與落點儀表板'!$B$14+Y673*'114成績輸入與落點儀表板'!$B$15+Z673*'114成績輸入與落點儀表板'!$B$16 -> 0 | I673: =IF(G673="","",H673-G673) -> -88 | J673: =IF(G673="","無錄取資料",IF(I673>=0,"PASS","FAIL")) -> FAIL | K673: =IF(AND(IF('114成績輸入與落點儀表板'!$C$2="必須採計",L673>0,IF('114成績輸入與落點儀表板'!$C$2="不可採計",L673=0,TRUE)),IF('114成績輸入與落點儀表板'!$C$3="必須採計",M673>0,IF('114成績輸入與落點儀表板'!$C$3="不可採計",M673=0,TRUE)),IF('114成績輸入與落點儀表板'!$C$4="必須採計",N673>0,IF('114成績輸入與落點儀表板'!$C$4="不可採計",N673=0,TRUE)),IF('114成績輸入與落點儀表板'!$C$5="必須採計",O673>0,IF('114成績輸入與落點儀表板'!$C$5="不可採計",O673=0,TRUE)),IF('114成績輸入與落點儀表板'!$C$6="必須採計",P673>0,IF('114成績輸入與落點儀表板'!$C$6="不可採計",P673=0,TRUE)),IF('114成績輸入與落點儀表板'!$C$7="必須採計",Q673>0,IF('114成績輸入與落點儀表板'!$C$7="不可採計",Q673=0,TRUE)),IF('114成績輸入與落點儀表板'!$C$8="必須採計",R673>0,IF('114成績輸入與落點儀表板'!$C$8="不可採計",R673=0,TRUE)),IF('114成績輸入與落點儀表板'!$C$9="必須採計",S673>0,IF('114成績輸入與落點儀表板'!$C$9="不可採計",S673=0,TRUE)),IF('114成績輸入與落點儀表板'!$C$10="必須採計",T673>0,IF('114成績輸入與落點儀表板'!$C$10="不可採計",T673=0,TRUE)),IF('114成績輸入與落點儀表板'!$C$11="必須採計",U673>0,IF('114成績輸入與落點儀表板'!$C$11="不可採計",U673=0,TRUE)),IF('114成績輸入與落點儀表板'!$C$12="必須採計",V673>0,IF('114成績輸入與落點儀表板'!$C$12="不可採計",V673=0,TRUE)),IF('114成績輸入與落點儀表板'!$C$13="必須採計",W673>0,IF('114成績輸入與落點儀表板'!$C$13="不可採計",W673=0,TRUE)),IF('114成績輸入與落點儀表板'!$C$14="必須採計",X673>0,IF('114成績輸入與落點儀表板'!$C$14="不可採計",X673=0,TRUE)),IF('114成績輸入與落點儀表板'!$C$15="必須採計",Y673>0,IF('114成績輸入與落點儀表板'!$C$15="不可採計",Y673=0,TRUE)),IF('114成績輸入與落點儀表板'!$C$16="必須採計",Z673>0,IF('114成績輸入與落點儀表板'!$C$16="不可採計",Z673=0,TRUE))),"✅ 符合","❌ 不符合") -> ✅ 符合 | L673: 2 | M673: 1.5 | N673: 0 | O673: 0 | P673: 0 | Q673: 0 | R673: 0 | S673: 0 | T673: 0 | U673: 1 | V673: 0 | W673: 0 | X673: 0 | Y673: 0 | Z673: 0
A674: 1241 | B674: 中國文化大學 | C674: 戲劇學系 | D674: 藝術與體育學群 | E674: 國x1.25 英x1.00 歷x1.00 | F674: 9 | G674: 91 | H674: =L674*'114成績輸入與落點儀表板'!$B$2+M674*'114成績輸入與落點儀表板'!$B$3+N674*'114成績輸入與落點儀表板'!$B$4+O674*'114成績輸入與落點儀表板'!$B$5+P674*'114成績輸入與落點儀表板'!$B$6+Q674*'114成績輸入與落點儀表板'!$B$7+R674*'114成績輸入與落點儀表板'!$B$8+S674*'114成績輸入與落點儀表板'!$B$9+T674*'114成績輸入與落點儀表板'!$B$10+U674*'114成績輸入與落點儀表板'!$B$11+V674*'114成績輸入與落點儀表板'!$B$12+W674*'114成績輸入與落點儀表板'!$B$13+X674*'114成績輸入與落點儀表板'!$B$14+Y674*'114成績輸入與落點儀表板'!$B$15+Z674*'114成績輸入與落點儀表板'!$B$16 -> 0 | I674: =IF(G674="","",H674-G674) -> -91 | J674: =IF(G674="","無錄取資料",IF(I674>=0,"PASS","FAIL")) -> FAIL | K674: =IF(AND(IF('114成績輸入與落點儀表板'!$C$2="必須採計",L674>0,IF('114成績輸入與落點儀表板'!$C$2="不可採計",L674=0,TRUE)),IF('114成績輸入與落點儀表板'!$C$3="必須採計",M674>0,IF('114成績輸入與落點儀表板'!$C$3="不可採計",M674=0,TRUE)),IF('114成績輸入與落點儀表板'!$C$4="必須採計",N674>0,IF('114成績輸入與落點儀表板'!$C$4="不可採計",N674=0,TRUE)),IF('114成績輸入與落點儀表板'!$C$5="必須採計",O674>0,IF('114成績輸入與落點儀表板'!$C$5="不可採計",O674=0,TRUE)),IF('114成績輸入與落點儀表板'!$C$6="必須採計",P674>0,IF('114成績輸入與落點儀表板'!$C$6="不可採計",P674=0,TRUE)),IF('114成績輸入與落點儀表板'!$C$7="必須採計",Q674>0,IF('114成績輸入與落點儀表板'!$C$7="不可採計",Q674=0,TRUE)),IF('114成績輸入與落點儀表板'!$C$8="必須採計",R674>0,IF('114成績輸入與落點儀表板'!$C$8="不可採計",R674=0,TRUE)),IF('114成績輸入與落點儀表板'!$C$9="必須採計",S674>0,IF('114成績輸入與落點儀表板'!$C$9="不可採計",S674=0,TRUE)),IF('114成績輸入與落點儀表板'!$C$10="必須採計",T674>0,IF('114成績輸入與落點儀表板'!$C$10="不可採計",T674=0,TRUE)),IF('114成績輸入與落點儀表板'!$C$11="必須採計",U674>0,IF('114成績輸入與落點儀表板'!$C$11="不可採計",U674=0,TRUE)),IF('114成績輸入與落點儀表板'!$C$12="必須採計",V674>0,IF('114成績輸入與落點儀表板'!$C$12="不可採計",V674=0,TRUE)),IF('114成績輸入與落點儀表板'!$C$13="必須採計",W674>0,IF('114成績輸入與落點儀表板'!$C$13="不可採計",W674=0,TRUE)),IF('114成績輸入與落點儀表板'!$C$14="必須採計",X674>0,IF('114成績輸入與落點儀表板'!$C$14="不可採計",X674=0,TRUE)),IF('114成績輸入與落點儀表板'!$C$15="必須採計",Y674>0,IF('114成績輸入與落點儀表板'!$C$15="不可採計",Y674=0,TRUE)),IF('114成績輸入與落點儀表板'!$C$16="必須採計",Z674>0,IF('114成績輸入與落點儀表板'!$C$16="不可採計",Z674=0,TRUE))),"✅ 符合","❌ 不符合") -> ✅ 符合 | L674: 1.25 | M674: 1 | N674: 0 | O674: 0 | P674: 0 | Q674: 0 | R674: 0 | S674: 0 | T674: 0 | U674: 1 | V674: 0 | W674: 0 | X674: 0 | Y674: 0 | Z674: 0
